Workbook
Name acq: 'A&R'!$D$13
Name Cir: 'A&R'!$I$9
Name exit: 'A&R'!$D$16
Name period: 'A&R'!$D$17
Name py: 'A&R'!$D$11
Name start: 'A&R'!$D$14
Name unit: 'A&R'!$D$10

Sheet A&R
B2: Team LAVEL | AF2: 변수입력 | AG2: 합계1 | AH2: 제목
B3: KBC타워 재무모델 | AF3: 적정성확인 | AG3: 합계2 | AH3: 표제목
AF4: 오류확인 | AG4: 합계3 | AH4: 작성자참고
A6: 단위: 백만원 | AH6: 45611
A7: Assumption & Result
B8: 기본가정 | U8: 운영비용 및 기타수입 가정
B9: •투자 Vehicle: | D9: 부동산펀드(REF) | G9: •Circulation Switch | I9: 1 | U9: 운영비용 가정 | AC9: Leasing비용 가정
B10: •화폐단위: | D10: 1000000 | E10: 원 | U10: 구분 | V10: 주요가정 | Z10: 비고 | AC10: 구분 | AD10: 주요가정
B11: •1㎡ = | D11: 0.3025 | E11: 평 | U11: PM Fee | V11: 평단가/월 | W11: 900 | X11: 연 상승률 | Y11: 0.025 | AC11: 재계약시 | AD11: 실질 월 임대료의 | AF11: 0.7
B12: •날짜입력: | D12: 월말기준 | U12: FM Fee | V12: 평단가/월 | W12: 11000 | X12: 연 상승률 | Y12: 0.025 | AC12: 신규계약시 | AD12: 실질 월 임대료의 | AF12: 2.1 | AG12: 최초 1기 6개월 지급이연
B13: •자산취득월: | D13: 45688 | U13: 수도광열비 | V13: 평단가/월 | W13: 8000 | X13: 연 상승률 | Y13: 0.025 | AG13: 대신 10%p 상향계약
B14: •자산운용시작월: | D14: =EOMONTH(D13,1) -> 45716 | U14: 유지관리비 | V14: 평단가/월 | W14: 3500 | X14: 연 상승률 | Y14: 0.025 | Z14: 매입 1달 후 30% 감소 | AC14: 기타수입 가정
B15: •자산운용기간: | D15: 5 | U15: 보험료 | V15: 평단가/월 | W15: 200 | X15: 연 상승률 | Y15: 0.025 | AC15: 구분 | AE15: 주요가정
B16: •자산매각월: | D16: =EOMONTH(D13,12*D15) -> 47514 | U16: 제세공과금 | V16: 매입가의 | W16: 0.005 | X16: 연 상승률 | Y16: 0.025 | AC16: 주차수입 | AE16: 40 | AF16: 백만원/월 | AG16: 연 상승률 | AH16: 0.025
B17: •회계기간: | D17: 6 | AC17: 기타수입 | AE17: 평단가/월 | AF17: 2000 | AG17: 연 상승률 | AH17: 0.025
B18: 자산개요 | U18: 펀드 및 기타비용 가정 | AC18: 전광판수입 | AE18: 240 | AF18: 백만원/월 | AG18: 연 상승률 | AH18: 0.025
B19: •자산명: | D19: KBC타워 | I19: •타입: | K19: 오피스(중대형, B Grade) | U19: 구분 | X19: 주요가정 | AC19: 옥외전광판 공사기간 1개월
B20: •위치: | D20: 서울시 중구 남대문로 125 | I20: •연면적: | K20: 25076 | L20: ㎡ ➔ | M20: =K20*py -> 7585.49 | N20: 평 | U20: 집합투자업자 운용보수 | X20: 400 | Y20: 백만원/년
B21: •용도지역: | D21: 일반상업지역 | I21: •준공연도: | K21: 40209 | L21: 년 | U21: 신탁업자 자산수탁 보수 | X21: 60 | Y21: 백만원/년
B22: •대지면적: | D22: 2115 | E22: ㎡ | F22: =D22*py -> 639.7875 | G22: 평 | I22: •건물규모: | K22: 지하5층 / 지상17층 | U22: 투자매매/중개업자 판매보수 | X22: 40 | Y22: 백만원/년
B23: •공시지가: | D23: 65430000 | E23: 원/㎡ ➔ | F23: =D22*D23/unit -> 138384.45 | G23: 백만원 | I23: •매입가 적정성: | K23: Stb Initial Cap | M23: =$G$27 -> 0.047656366 | U23: 일반사무관리회사 업무보수 | X23: 25 | Y23: 백만원/년
B24: •기존 Rentroll 공실률: | D24: =SUM(Rentroll!F23:F26)/Rentroll!F32 -> 0.22099455 | K24: 연면적당 매입가 | M24: =E27/M20 -> 31.112031 | N24: 백만원/평 | U24: Other Fees (Acc./Tax/etc.) | X24: 45 | Y24: 백만원/년
B25: 투자비 산정 | U25: 자산매각 가정
B26: 구분 | E26: 금액 | F26: 산정근거 | I26: 비율 | J26: 비고 | U26: 1. 연차별 NOI산정
B27: 매입가격 | E27: 236000 | F27: Stb Initial Cap | G27: =$AF$44/($E$27-$E$54) -> 0.047656366 | I27: =E27/$E$43 -> 0.91291074 | K27: Going-in Cap | M27: =$AH$44/($E$27-$E$54) -> 0.036638203 | U27: 연차 | X27: 합게 | Y27: 1 | Z27: 2 | AA27: 3 | AB27: 4 | AC27: 5 | AD27: 6 | AE27: 7 | AF27: 8 | AG27: 9 | AH27: 10
B28: 부대비용 | E28: =SUM(E29:E31) -> 13480 | I28: =E28/$E$43 -> 0.052144224 | L28: =I28+I32 -> 0.054397022 | M28: =E28+E32 -> 14062.379 | U28: 운영수입 | X28: =SUM(Y28:AH28) -> 81962.918 | Y28: =SUM(Y29:Y33) -> 14253.082 | Z28: =SUM(Z29:Z33) -> 15959.019 | AA28: =SUM(AA29:AA33) -> 16464.692 | AB28: =SUM(AB29:AB33) -> 17274.609 | AC28: =SUM(AC29:AC33) -> 18011.516 | AD28: =SUM(AD29:AD33) -> 0 | AE28: =SUM(AE29:AE33) -> 0 | AF28: =SUM(AF29:AF33) -> 0 | ... AH28: =SUM(AH29:AH33) -> 0
C29: AMC 매입보수 | E29: =E27*G29 -> 1652 | F29: 매입가의 | G29: 0.007 | V29: 임대료 수입 | W29: =ABS(X29-운영수입!Q18)<0.001 -> TRUE | X29: =SUM(Y29:AH29) -> 42367.537 | Y29: =SUMIF(운영수입!$S$16:$DM$16,Y$27,운영수입!$S$18:$DM$18) -> 7028.616 | Z29: =SUMIF(운영수입!$S$16:$DM$16,Z$27,운영수입!$S$18:$DM$18) -> 8216.2367 | AA29: =SUMIF(운영수입!$S$16:$DM$16,AA$27,운영수입!$S$18:$DM$18) -> 8467.0596 | AB29: =SUMIF(운영수입!$S$16:$DM$16,AB$27,운영수입!$S$18:$DM$18) -> 9065.4481 | AC29: =SUMIF(운영수입!$S$16:$DM$16,AC$27,운영수입!$S$18:$DM$18) -> 9590.1767 | AD29: =SUMIF(운영수입!$S$16:$DM$16,AD$27,운영수입!$S$18:$DM$18) -> 0 | AE29: =SUMIF(운영수입!$S$16:$DM$16,AE$27,운영수입!$S$18:$DM$18) -> 0 | AF29: =SUMIF(운영수입!$S$16:$DM$16,AF$27,운영수입!$S$18:$DM$18) -> 0 | ... AH29: =SUMIF(운영수입!$S$16:$DM$16,AH$27,운영수입!$S$18:$DM$18) -> 0
C30: 소유권 이전비용 | E30: =E27*G30 -> 11328 | F30: 매입가의 | G30: 0.048 | J30: 취득세, 담보설정비용 포함 | V30: 관리비 수입 | W30: =ABS(X30-운영수입!Q65)<0.001 -> TRUE | X30: =SUM(Y30:AH30) -> 21242.108 | Y30: =SUMIF(운영수입!$S$16:$DM$16,Y$27,운영수입!$S$65:$DM$65) -> 3922.4142 | Z30: =SUMIF(운영수입!$S$16:$DM$16,Z$27,운영수입!$S$65:$DM$65) -> 4118.1793 | AA30: =SUMIF(운영수입!$S$16:$DM$16,AA$27,운영수입!$S$65:$DM$65) -> 4282.414 | AB30: =SUMIF(운영수입!$S$16:$DM$16,AB$27,운영수입!$S$65:$DM$65) -> 4401.0627 | AC30: =SUMIF(운영수입!$S$16:$DM$16,AC$27,운영수입!$S$65:$DM$65) -> 4518.038 | AD30: =SUMIF(운영수입!$S$16:$DM$16,AD$27,운영수입!$S$65:$DM$65) -> 0 | AE30: =SUMIF(운영수입!$S$16:$DM$16,AE$27,운영수입!$S$65:$DM$65) -> 0 | AF30: =SUMIF(운영수입!$S$16:$DM$16,AF$27,운영수입!$S$65:$DM$65) -> 0 | ... AH30: =SUMIF(운영수입!$S$16:$DM$16,AH$27,운영수입!$S$65:$DM$65) -> 0
C31: 실사비용 | E31: 500 | F31: 기본가정사항 | V31: 주차수입 | W31: =ABS(X31-운영수입!Q170)<0.001 -> TRUE | X31: =SUM(Y31:AH31) -> 2523.0377 | Y31: =SUMIF(운영수입!$S$16:$DM$16,Y$27,운영수입!$S$170:$DM$170) -> 480 | Z31: =SUMIF(운영수입!$S$16:$DM$16,Z$27,운영수입!$S$170:$DM$170) -> 492 | AA31: =SUMIF(운영수입!$S$16:$DM$16,AA$27,운영수입!$S$170:$DM$170) -> 504.3 | AB31: =SUMIF(운영수입!$S$16:$DM$16,AB$27,운영수입!$S$170:$DM$170) -> 516.9075 | AC31: =SUMIF(운영수입!$S$16:$DM$16,AC$27,운영수입!$S$170:$DM$170) -> 529.83019 | AD31: =SUMIF(운영수입!$S$16:$DM$16,AD$27,운영수입!$S$170:$DM$170) -> 0 | AE31: =SUMIF(운영수입!$S$16:$DM$16,AE$27,운영수입!$S$170:$DM$170) -> 0 | AF31: =SUMIF(운영수입!$S$16:$DM$16,AF$27,운영수입!$S$170:$DM$170) -> 0 | ... AH31: =SUMIF(운영수입!$S$16:$DM$16,AH$27,운영수입!$S$170:$DM$170) -> 0
B32: 금융비용 | E32: =E33 -> 582.37934 | I32: =E32/$E$43 -> 0.0022527981 | V32: 기타수입 | W32: =ABS(X32-운영수입!Q175)<0.001 -> TRUE | X32: =SUM(Y32:AH32) -> 956.92386 | Y32: =SUMIF(운영수입!$S$16:$DM$16,Y$27,운영수입!$S$175:$DM$175) -> 182.05176 | Z32: =SUMIF(운영수입!$S$16:$DM$16,Z$27,운영수입!$S$175:$DM$175) -> 186.60305 | AA32: =SUMIF(운영수입!$S$16:$DM$16,AA$27,운영수입!$S$175:$DM$175) -> 191.26813 | AB32: =SUMIF(운영수입!$S$16:$DM$16,AB$27,운영수입!$S$175:$DM$175) -> 196.04983 | AC32: =SUMIF(운영수입!$S$16:$DM$16,AC$27,운영수입!$S$175:$DM$175) -> 200.95108 | AD32: =SUMIF(운영수입!$S$16:$DM$16,AD$27,운영수입!$S$175:$DM$175) -> 0 | AE32: =SUMIF(운영수입!$S$16:$DM$16,AE$27,운영수입!$S$175:$DM$175) -> 0 | AF32: =SUMIF(운영수입!$S$16:$DM$16,AF$27,운영수입!$S$175:$DM$175) -> 0 | ... AH32: =SUMIF(운영수입!$S$16:$DM$16,AH$27,운영수입!$S$175:$DM$175) -> 0
C33: 대출취급수수료 | E33: =(E52*J52)+(E53*J53) -> 582.37934 | F33: 재원조달계획 참조 | V33: 전광판 수입 | W33: =ABS(X33-운영수입!Q180)<0.001 -> TRUE | X33: =SUM(Y33:AH33) -> 14873.311 | Y33: =SUMIF(운영수입!$16:$16,'A&R'!Y27,운영수입!$180:$180) -> 2640 | Z33: =SUMIF(운영수입!$16:$16,'A&R'!Z27,운영수입!$180:$180) -> 2946 | AA33: =SUMIF(운영수입!$16:$16,'A&R'!AA27,운영수입!$180:$180) -> 3019.65 | AB33: =SUMIF(운영수입!$16:$16,'A&R'!AB27,운영수입!$180:$180) -> 3095.1413 | AC33: =SUMIF(운영수입!$16:$16,'A&R'!AC27,운영수입!$180:$180) -> 3172.5198 | AD33: =SUMIF(운영수입!$16:$16,'A&R'!AD27,운영수입!$180:$180) -> 0 | AE33: =SUMIF(운영수입!$16:$16,'A&R'!AE27,운영수입!$180:$180) -> 0 | AF33: =SUMIF(운영수입!$16:$16,'A&R'!AF27,운영수입!$180:$180) -> 0 | ... AH33: =SUMIF(운영수입!$16:$16,'A&R'!AH27,운영수입!$180:$180) -> 0
B34: 공사비용 | E34: =SUM(E35:E39) -> 6600 | I34: =E34/$E$43 -> 0.025530555 | U34: (-)운영비용 | X34: =SUM(Y34:AH34) -> 18020.536 | Y34: =SUM(Y35:Y41) -> 3779.6703 | Z34: =SUM(Z35:Z41) -> 3345.5488 | AA34: =SUM(AA35:AA41) -> 3692.7884 | AB34: =SUM(AB35:AB41) -> 3634.3059 | AC34: =SUM(AC35:AC41) -> 3568.2226 | AD34: =SUM(AD35:AD41) -> 0 | AE34: =SUM(AE35:AE41) -> 0 | AF34: =SUM(AF35:AF41) -> 0 | ... AH34: =SUM(AH35:AH41) -> 0
C35: 로비환경개선공사 | E35: 3000 | F35: 기본가정사항 | V35: =U11 -> PM Fee | X35: =SUM(Y35:AH35) -> 430.61574 | Y35: =SUMIF(운영비용!$H$16:$DB$16,'A&R'!Y$27,운영비용!$H$20:$DB$20) -> 81.923292 | Z35: =SUMIF(운영비용!$H$16:$DB$16,'A&R'!Z$27,운영비용!$H$20:$DB$20) -> 83.971374 | AA35: =SUMIF(운영비용!$H$16:$DB$16,'A&R'!AA$27,운영비용!$H$20:$DB$20) -> 86.070659 | AB35: =SUMIF(운영비용!$H$16:$DB$16,'A&R'!AB$27,운영비용!$H$20:$DB$20) -> 88.222425 | AC35: =SUMIF(운영비용!$H$16:$DB$16,'A&R'!AC$27,운영비용!$H$20:$DB$20) -> 90.427986 | AD35: =SUMIF(운영비용!$H$16:$DB$16,'A&R'!AD$27,운영비용!$H$20:$DB$20) -> 0 | AE35: =SUMIF(운영비용!$H$16:$DB$16,'A&R'!AE$27,운영비용!$H$20:$DB$20) -> 0 | AF35: =SUMIF(운영비용!$H$16:$DB$16,'A&R'!AF$27,운영비용!$H$20:$DB$20) -> 0 | ... AH35: =SUMIF(운영비용!$H$16:$DB$16,'A&R'!AH$27,운영비용!$H$20:$DB$20) -> 0
C36: 용도변경공사 | E36: 300 | F36: 기본가정사항 | V36: =U12 -> FM Fee | X36: =SUM(Y36:AH36) -> 5263.0812 | Y36: =SUMIF(운영비용!$H$16:$DB$16,'A&R'!Y$27,운영비용!$H$25:$DB$25) -> 1001.2847 | Z36: =SUMIF(운영비용!$H$16:$DB$16,'A&R'!Z$27,운영비용!$H$25:$DB$25) -> 1026.3168 | AA36: =SUMIF(운영비용!$H$16:$DB$16,'A&R'!AA$27,운영비용!$H$25:$DB$25) -> 1051.9747 | AB36: =SUMIF(운영비용!$H$16:$DB$16,'A&R'!AB$27,운영비용!$H$25:$DB$25) -> 1078.2741 | AC36: =SUMIF(운영비용!$H$16:$DB$16,'A&R'!AC$27,운영비용!$H$25:$DB$25) -> 1105.2309 | AD36: =SUMIF(운영비용!$H$16:$DB$16,'A&R'!AD$27,운영비용!$H$25:$DB$25) -> 0 | AE36: =SUMIF(운영비용!$H$16:$DB$16,'A&R'!AE$27,운영비용!$H$25:$DB$25) -> 0 | AF36: =SUMIF(운영비용!$H$16:$DB$16,'A&R'!AF$27,운영비용!$H$25:$DB$25) -> 0 | ... AH36: =SUMIF(운영비용!$H$16:$DB$16,'A&R'!AH$27,운영비용!$H$25:$DB$25) -> 0
C37: 에스컬레이터 증설 | E37: 100 | F37: 기본가정사항 | V37: =U13 -> 수도광열비 | X37: =SUM(Y37:AH37) -> 3827.6954 | Y37: =SUMIF(운영비용!$H$16:$DB$16,'A&R'!Y$27,운영비용!$H$30:$DB$30) -> 728.20704 | Z37: =SUMIF(운영비용!$H$16:$DB$16,'A&R'!Z$27,운영비용!$H$30:$DB$30) -> 746.41222 | AA37: =SUMIF(운영비용!$H$16:$DB$16,'A&R'!AA$27,운영비용!$H$30:$DB$30) -> 765.07252 | AB37: =SUMIF(운영비용!$H$16:$DB$16,'A&R'!AB$27,운영비용!$H$30:$DB$30) -> 784.19933 | AC37: =SUMIF(운영비용!$H$16:$DB$16,'A&R'!AC$27,운영비용!$H$30:$DB$30) -> 803.80432 | AD37: =SUMIF(운영비용!$H$16:$DB$16,'A&R'!AD$27,운영비용!$H$30:$DB$30) -> 0 | AE37: =SUMIF(운영비용!$H$16:$DB$16,'A&R'!AE$27,운영비용!$H$30:$DB$30) -> 0 | AF37: =SUMIF(운영비용!$H$16:$DB$16,'A&R'!AF$27,운영비용!$H$30:$DB$30) -> 0 | ... AH37: =SUMIF(운영비용!$H$16:$DB$16,'A&R'!AH$27,운영비용!$H$30:$DB$30) -> 0
C38: 기계/설비 교체 | E38: 2000 | F38: 기본가정사항 | V38: =U14 -> 유지관리비 | X38: =SUM(Y38:AH38) -> 1180.1965 | Y38: =SUMIF(운영비용!$H$16:$DB$16,'A&R'!Y$27,운영비용!$H$35:$DB$35) -> 230.97817 | Z38: =SUMIF(운영비용!$H$16:$DB$16,'A&R'!Z$27,운영비용!$H$35:$DB$35) -> 228.58874 | AA38: =SUMIF(운영비용!$H$16:$DB$16,'A&R'!AA$27,운영비용!$H$35:$DB$35) -> 234.30346 | AB38: =SUMIF(운영비용!$H$16:$DB$16,'A&R'!AB$27,운영비용!$H$35:$DB$35) -> 240.16105 | AC38: =SUMIF(운영비용!$H$16:$DB$16,'A&R'!AC$27,운영비용!$H$35:$DB$35) -> 246.16507 | AD38: =SUMIF(운영비용!$H$16:$DB$16,'A&R'!AD$27,운영비용!$H$35:$DB$35) -> 0 | AE38: =SUMIF(운영비용!$H$16:$DB$16,'A&R'!AE$27,운영비용!$H$35:$DB$35) -> 0 | AF38: =SUMIF(운영비용!$H$16:$DB$16,'A&R'!AF$27,운영비용!$H$35:$DB$35) -> 0 | ... AH38: =SUMIF(운영비용!$H$16:$DB$16,'A&R'!AH$27,운영비용!$H$35:$DB$35) -> 0
C39: 기타 공사비 | E39: 1200 | J39: 커튼월, 테라스공사, 옥외전광판 설치 등 | V39: =U15 -> 보험료 | X39: =SUM(Y39:AH39) -> 95.692386 | Y39: =SUMIF(운영비용!$H$16:$DB$16,'A&R'!Y$27,운영비용!$H$40:$DB$40) -> 18.205176 | Z39: =SUMIF(운영비용!$H$16:$DB$16,'A&R'!Z$27,운영비용!$H$40:$DB$40) -> 18.660305 | AA39: =SUMIF(운영비용!$H$16:$DB$16,'A&R'!AA$27,운영비용!$H$40:$DB$40) -> 19.126813 | AB39: =SUMIF(운영비용!$H$16:$DB$16,'A&R'!AB$27,운영비용!$H$40:$DB$40) -> 19.604983 | AC39: =SUMIF(운영비용!$H$16:$DB$16,'A&R'!AC$27,운영비용!$H$40:$DB$40) -> 20.095108 | AD39: =SUMIF(운영비용!$H$16:$DB$16,'A&R'!AD$27,운영비용!$H$40:$DB$40) -> 0 | AE39: =SUMIF(운영비용!$H$16:$DB$16,'A&R'!AE$27,운영비용!$H$40:$DB$40) -> 0 | AF39: =SUMIF(운영비용!$H$16:$DB$16,'A&R'!AF$27,운영비용!$H$40:$DB$40) -> 0 | ... AH39: =SUMIF(운영비용!$H$16:$DB$16,'A&R'!AH$27,운영비용!$H$40:$DB$40) -> 0
B40: 기타예비비 | E40: =SUM(E41:E42) -> 1851.3938 | I40: =E40/$E$43 -> 0.0071616835 | V40: =U16 -> 제세공과금 | X40: =SUM(Y40:AH40) -> 6202.4676 | Y40: =SUMIF(운영비용!$H$16:$DB$16,'A&R'!Y$27,운영비용!$H$45:$DB$45) -> 1180 | Z40: =SUMIF(운영비용!$H$16:$DB$16,'A&R'!Z$27,운영비용!$H$45:$DB$45) -> 1209.5 | AA40: =SUMIF(운영비용!$H$16:$DB$16,'A&R'!AA$27,운영비용!$H$45:$DB$45) -> 1239.7375 | AB40: =SUMIF(운영비용!$H$16:$DB$16,'A&R'!AB$27,운영비용!$H$45:$DB$45) -> 1270.7309 | AC40: =SUMIF(운영비용!$H$16:$DB$16,'A&R'!AC$27,운영비용!$H$45:$DB$45) -> 1302.4992 | AD40: =SUMIF(운영비용!$H$16:$DB$16,'A&R'!AD$27,운영비용!$H$45:$DB$45) -> 0 | AE40: =SUMIF(운영비용!$H$16:$DB$16,'A&R'!AE$27,운영비용!$H$45:$DB$45) -> 0 | AF40: =SUMIF(운영비용!$H$16:$DB$16,'A&R'!AF$27,운영비용!$H$45:$DB$45) -> 0 | ... AH40: =SUMIF(운영비용!$H$16:$DB$16,'A&R'!AH$27,운영비용!$H$45:$DB$45) -> 0
C41: 임차인유치비용(TI) | E41: =Rentroll!AC63 -> 251.39383 | F41: Rentroll 참조 | V41: Leasing 비용 | X41: =SUM(Y41:AH41) -> 1020.7871 | Y41: =SUMIF(운영비용!$H$16:$DB$16,'A&R'!Y$27,운영비용!$H$73:$DB$73) -> 539.07189 | Z41: =SUMIF(운영비용!$H$16:$DB$16,'A&R'!Z$27,운영비용!$H$73:$DB$73) -> 32.09936 | AA41: =SUMIF(운영비용!$H$16:$DB$16,'A&R'!AA$27,운영비용!$H$73:$DB$73) -> 296.50276 | AB41: =SUMIF(운영비용!$H$16:$DB$16,'A&R'!AB$27,운영비용!$H$73:$DB$73) -> 153.11307 | AC41: =SUMIF(운영비용!$H$16:$DB$16,'A&R'!AC$27,운영비용!$H$73:$DB$73) -> 0 | AD41: =SUMIF(운영비용!$H$16:$DB$16,'A&R'!AD$27,운영비용!$H$73:$DB$73) -> 0 | AE41: =SUMIF(운영비용!$H$16:$DB$16,'A&R'!AE$27,운영비용!$H$73:$DB$73) -> 0 | AF41: =SUMIF(운영비용!$H$16:$DB$16,'A&R'!AF$27,운영비용!$H$73:$DB$73) -> 0 | ... AH41: =SUMIF(운영비용!$H$16:$DB$16,'A&R'!AH$27,운영비용!$H$73:$DB$73) -> 0
C42: 순수 예비비 | E42: 1600 | U42: NOI | X42: =SUM(Y42:AH42) -> 63942.382 | Y42: =Y28-Y34 -> 10473.412 | Z42: =Z28-Z34 -> 12613.47 | AA42: =AA28-AA34 -> 12771.903 | AB42: =AB28-AB34 -> 13640.304 | AC42: =AC28-AC34 -> 14443.293 | AD42: =AD28-AD34 -> 0 | AE42: =AE28-AE34 -> 0 | AF42: =AF28-AF34 -> 0 | ... AH42: =AH28-AH34 -> 0
...

Sheet Rentroll
B2: Team LAVEL | E2: 재계약 및 임차확약 | W2: 변수입력 | X2: 합계1 | Y2: 제목
B3: KBC타워 재무모델 | E3: 신규 계약 | W3: 적정성확인 | X3: 합계2 | Y3: 표제목
E4: 운용기간과 무관 | W4: 오류확인 | X4: 합계3 | Y4: 작성자참고
A6: 단위: 백만원
A7: Rentroll
C8: 현 임대차 계약 | AC8: 보증금이자율 | AE8: 0.03
C9: 층수 | D9: 용도 | E9: 임차인 | F9: 면적 정보(㎡) | H9: 면적 정보(py) | J9: 전용률 | K9: 계약기간 | N9: 임대단가(원/py) | R9: TI (원/py) | S9: Fitout (개월) | T9: Rentfree (개월) | U9: 연상승률 | W9: NOC(원/py) | Y9: 보증금총액 (백만원) | Z9: 연 운영수입 (백만원) | AA9: 매입시 잔존월수
F10: 임대면적 | G10: 전용면적 | H10: 임대면적 | I10: 전용면적 | K10: 시작월 | L10: 종료월 | M10: 기간 | N10: 보증금 | O10: 명목 임대료 | P10: 실질 임대료 | Q10: 관리비 | U10: 임대료 | V10: 관리비 | W10: F.NOC | X10: E.NOC
C11: 17 | D11: Office | E11: 리마 상사 | F11: 1385.09 | G11: 683.57 | H11: =F11*py -> 418.98972 | I11: =G11*py -> 206.77993 | J11: =G11/F11 -> 0.49352028 | K11: 45322 | L11: 47148 | M11: =DATEDIF(K11,EOMONTH(L11,0),"m") -> 60 | N11: =O11*10 -> 1000000 | O11: 100000 | P11: =O11*(12-T11)/12 -> 75000 | Q11: 45000 | R11: 0 | S11: 0 | T11: 3 | U11: 0.03 | V11: 0.03 | W11: =(($O11+$Q11))/$J11 -> 293807.58 | X11: =IFERROR(((N11*$AE$8/12+$O11*($M11-$S11-($T11*M11/12))/$M11)+$Q11)/$J11-R11/M11,0) -> 248216.75 | Y11: =N11*H11/unit -> 418.98972 | Z11: =(P11*H11/unit+Q11*H11/unit)*12 -> 603.3452 | AA11: =IFERROR(DATEDIF(acq,$L11,"m"),0) -> 47
C12: 16 | D12: Office | E12: 리마 상사 | F12: 1385.09 | G12: 683.57 | H12: =F12*py -> 418.98972 | I12: =G12*py -> 206.77993 | J12: =G12/F12 -> 0.49352028 | K12: 45322 | L12: 47148 | M12: =DATEDIF(K12,EOMONTH(L12,0),"m") -> 60 | N12: =O12*10 -> 1000000 | O12: 100000 | P12: =O12*(12-T12)/12 -> 75000 | Q12: 45000 | R12: 0 | S12: 0 | T12: 3 | U12: 0.03 | V12: 0.03 | W12: =(($O12+$Q12))/$J12 -> 293807.58 | X12: =IFERROR(((N12*$AE$8/12+$O12*($M12-$S12-($T12*M12/12))/$M12)+$Q12)/$J12-R12/M12,0) -> 248216.75 | Y12: =N12*H12/unit -> 418.98972 | Z12: =(P12*H12/unit+Q12*H12/unit)*12 -> 603.3452 | AA12: =IFERROR(DATEDIF(acq,$L12,"m"),0) -> 47
C13: 15 | D13: Office | E13: 모빌리티 테크놀로지 | F13: 1385.09 | G13: 683.57 | H13: =F13*py -> 418.98972 | I13: =G13*py -> 206.77993 | J13: =G13/F13 -> 0.49352028 | K13: 44042 | L13: 45869 | M13: =DATEDIF(K13,EOMONTH(L13,0),"m") -> 60 | N13: 800000 | O13: 90041 | P13: =O13*(12-T13)/12 -> 67530.75 | Q13: 45020 | R13: 0 | S13: 0 | T13: 3 | U13: 0.03 | V13: 0.03 | W13: =(($O13+$Q13))/$J13 -> 273668.59 | X13: =IFERROR(((N13*$AE$8/12+$O13*($M13-$S13-($T13*M13/12))/$M13)+$Q13)/$J13-R13/M13,0) -> 232109.51 | Y13: =N13*H13/unit -> 335.19178 | Z13: =(P13*H13/unit+Q13*H13/unit)*12 -> 565.89129 | AA13: =IFERROR(DATEDIF(acq,$L13,"m"),0) -> 6
C14: 14 | D14: Office | E14: 모빌리티 테크놀로지 | F14: 1385.09 | G14: 683.57 | H14: =F14*py -> 418.98972 | I14: =G14*py -> 206.77993 | J14: =G14/F14 -> 0.49352028 | K14: 44043 | L14: 45868 | M14: =DATEDIF(K14,EOMONTH(L14,0),"m") -> 60 | N14: 800000 | O14: 90041 | P14: =O14*(12-T14)/12 -> 67530.75 | Q14: 45020 | R14: 0 | S14: 0 | T14: 3 | U14: 0.03 | V14: 0.03 | W14: =(($O14+$Q14))/$J14 -> 273668.59 | X14: =IFERROR(((N14*$AE$8/12+$O14*($M14-$S14-($T14*M14/12))/$M14)+$Q14)/$J14-R14/M14,0) -> 232109.51 | Y14: =N14*H14/unit -> 335.19178 | Z14: =(P14*H14/unit+Q14*H14/unit)*12 -> 565.89129 | AA14: =IFERROR(DATEDIF(acq,$L14,"m"),0) -> 5
C15: 13 | D15: Office | E15: 모빌리티 테크놀로지 | F15: 1385.09 | G15: 683.57 | H15: =F15*py -> 418.98972 | I15: =G15*py -> 206.77993 | J15: =G15/F15 -> 0.49352028 | K15: 44043 | L15: 45868 | M15: =DATEDIF(K15,EOMONTH(L15,0),"m") -> 60 | N15: 800000 | O15: 90041 | P15: =O15*(12-T15)/12 -> 67530.75 | Q15: 45020 | R15: 0 | S15: 0 | T15: 3 | U15: 0.03 | V15: 0.03 | W15: =(($O15+$Q15))/$J15 -> 273668.59 | X15: =IFERROR(((N15*$AE$8/12+$O15*($M15-$S15-($T15*M15/12))/$M15)+$Q15)/$J15-R15/M15,0) -> 232109.51 | Y15: =N15*H15/unit -> 335.19178 | Z15: =(P15*H15/unit+Q15*H15/unit)*12 -> 565.89129 | AA15: =IFERROR(DATEDIF(acq,$L15,"m"),0) -> 5
C16: 12 | D16: Office | E16: 모빌리티 테크놀로지 | F16: 1385.09 | G16: 683.57 | H16: =F16*py -> 418.98972 | I16: =G16*py -> 206.77993 | J16: =G16/F16 -> 0.49352028 | K16: 44043 | L16: 45868 | M16: =DATEDIF(K16,EOMONTH(L16,0),"m") -> 60 | N16: 800000 | O16: 90041 | P16: =O16*(12-T16)/12 -> 67530.75 | Q16: 45020 | R16: 0 | S16: 0 | T16: 3 | U16: 0.03 | V16: 0.03 | W16: =(($O16+$Q16))/$J16 -> 273668.59 | X16: =IFERROR(((N16*$AE$8/12+$O16*($M16-$S16-($T16*M16/12))/$M16)+$Q16)/$J16-R16/M16,0) -> 232109.51 | Y16: =N16*H16/unit -> 335.19178 | Z16: =(P16*H16/unit+Q16*H16/unit)*12 -> 565.89129 | AA16: =IFERROR(DATEDIF(acq,$L16,"m"),0) -> 5
C17: 11 | D17: Office | E17: 노벰버 건설 | F17: 1385.09 | G17: 683.57 | H17: =F17*py -> 418.98972 | I17: =G17*py -> 206.77993 | J17: =G17/F17 -> 0.49352028 | K17: 45077 | L17: 46903 | M17: =DATEDIF(K17,EOMONTH(L17,0),"m") -> 60 | N17: 1000000 | O17: 103000 | P17: =O17*(12-T17)/12 -> 85833.333 | Q17: 46350 | R17: 0 | S17: 0 | T17: 2 | U17: 0.03 | V17: 0.03 | W17: =(($O17+$Q17))/$J17 -> 302621.81 | X17: =IFERROR(((N17*$AE$8/12+$O17*($M17-$S17-($T17*M17/12))/$M17)+$Q17)/$J17-R17/M17,0) -> 272903.34 | Y17: =N17*H17/unit -> 418.98972 | Z17: =(P17*H17/unit+Q17*H17/unit)*12 -> 664.6015 | AA17: =IFERROR(DATEDIF(acq,$L17,"m"),0) -> 39
C18: 10 | D18: Office | E18: 노벰버 건설 | F18: 1385.09 | G18: 683.57 | H18: =F18*py -> 418.98972 | I18: =G18*py -> 206.77993 | J18: =G18/F18 -> 0.49352028 | K18: 45077 | L18: 46903 | M18: =DATEDIF(K18,EOMONTH(L18,0),"m") -> 60 | N18: 1000000 | O18: 103000 | P18: =O18*(12-T18)/12 -> 85833.333 | Q18: 46350 | R18: 0 | S18: 0 | T18: 2 | U18: 0.03 | V18: 0.03 | W18: =(($O18+$Q18))/$J18 -> 302621.81 | X18: =IFERROR(((N18*$AE$8/12+$O18*($M18-$S18-($T18*M18/12))/$M18)+$Q18)/$J18-R18/M18,0) -> 272903.34 | Y18: =N18*H18/unit -> 418.98972 | Z18: =(P18*H18/unit+Q18*H18/unit)*12 -> 664.6015 | AA18: =IFERROR(DATEDIF(acq,$L18,"m"),0) -> 39 | AC18: 신규 임대차 변수
C19: 9 | D19: Office | E19: 노벰버 건설 | F19: 1385.09 | G19: 683.57 | H19: =F19*py -> 418.98972 | I19: =G19*py -> 206.77993 | J19: =G19/F19 -> 0.49352028 | K19: 45077 | L19: 46903 | M19: =DATEDIF(K19,EOMONTH(L19,0),"m") -> 60 | N19: 1000000 | O19: 103000 | P19: =O19*(12-T19)/12 -> 85833.333 | Q19: 46350 | R19: 0 | S19: 0 | T19: 2 | U19: 0.03 | V19: 0.03 | W19: =(($O19+$Q19))/$J19 -> 302621.81 | X19: =IFERROR(((N19*$AE$8/12+$O19*($M19-$S19-($T19*M19/12))/$M19)+$Q19)/$J19-R19/M19,0) -> 272903.34 | Y19: =N19*H19/unit -> 418.98972 | Z19: =(P19*H19/unit+Q19*H19/unit)*12 -> 664.6015 | AA19: =IFERROR(DATEDIF(acq,$L19,"m"),0) -> 39 | AC19: 오피스 임대료 | AE19: ='A&R'!AG109 -> 103000
C20: 8 | D20: Office | E20: 오토 커머셜 | F20: 1385.09 | G20: 683.57 | H20: =F20*py -> 418.98972 | I20: =G20*py -> 206.77993 | J20: =G20/F20 -> 0.49352028 | K20: 44651 | L20: 46476 | M20: =DATEDIF(K20,EOMONTH(L20,0),"m") -> 60 | N20: 900000 | O20: 95481 | P20: =O20*(12-T20)/12 -> 87524.25 | Q20: 42436 | R20: 0 | S20: 0 | T20: 1 | U20: 0.03 | V20: 0.03 | W20: =(($O20+$Q20))/$J20 -> 279455.59 | X20: =IFERROR(((N20*$AE$8/12+$O20*($M20-$S20-($T20*M20/12))/$M20)+$Q20)/$J20-R20/M20,0) -> 267892.24 | Y20: =N20*H20/unit -> 377.09075 | Z20: =(P20*H20/unit+Q20*H20/unit)*12 -> 653.42411 | AA20: =IFERROR(DATEDIF(acq,$L20,"m"),0) -> 25 | AC20: 오피스 관리비 | AE20: 45000
C21: 7 | D21: Office | E21: 오토 커머셜 | F21: 1385.09 | G21: 683.57 | H21: =F21*py -> 418.98972 | I21: =G21*py -> 206.77993 | J21: =G21/F21 -> 0.49352028 | K21: 44651 | L21: 46476 | M21: =DATEDIF(K21,EOMONTH(L21,0),"m") -> 60 | N21: 900000 | O21: 95481 | P21: =O21*(12-T21)/12 -> 87524.25 | Q21: 42436 | R21: 0 | S21: 0 | T21: 1 | U21: 0.03 | V21: 0.03 | W21: =(($O21+$Q21))/$J21 -> 279455.59 | X21: =IFERROR(((N21*$AE$8/12+$O21*($M21-$S21-($T21*M21/12))/$M21)+$Q21)/$J21-R21/M21,0) -> 267892.24 | Y21: =N21*H21/unit -> 377.09075 | Z21: =(P21*H21/unit+Q21*H21/unit)*12 -> 653.42411 | AA21: =IFERROR(DATEDIF(acq,$L21,"m"),0) -> 25 | AC21: 1F 대비 B1 효용비율 | AE21: 0.3275
C22: 6 | D22: Office | E22: 오토 커머셜 | F22: 1385.09 | G22: 683.57 | H22: =F22*py -> 418.98972 | I22: =G22*py -> 206.77993 | J22: =G22/F22 -> 0.49352028 | K22: 44651 | L22: 46476 | M22: =DATEDIF(K22,EOMONTH(L22,0),"m") -> 60 | N22: 900000 | O22: 95481 | P22: =O22*(12-T22)/12 -> 87524.25 | Q22: 42436 | R22: 0 | S22: 0 | T22: 1 | U22: 0.03 | V22: 0.03 | W22: =(($O22+$Q22))/$J22 -> 279455.59 | X22: =IFERROR(((N22*$AE$8/12+$O22*($M22-$S22-($T22*M22/12))/$M22)+$Q22)/$J22-R22/M22,0) -> 267892.24 | Y22: =N22*H22/unit -> 377.09075 | Z22: =(P22*H22/unit+Q22*H22/unit)*12 -> 653.42411 | AA22: =IFERROR(DATEDIF(acq,$L22,"m"),0) -> 25
C23: 5 | D23: Office | E23: 공실 | F23: 1385.09 | G23: 683.57 | H23: =F23*py -> 418.98972 | I23: =G23*py -> 206.77993 | J23: =G23/F23 -> 0.49352028 | M23: =DATEDIF(K23,EOMONTH(L23,0),"m") -> 0 | N23: =O23*10 -> 0 | O23: 0 | P23: =O23*(12-T23)/12 -> 0 | Q23: 0 | R23: 0 | S23: 0 | T23: 0 | U23: 0 | V23: 0 | W23: =(($O23+$Q23))/$J23 -> 0 | X23: =IFERROR(((N23*$AE$8/12+$O23*($M23-$S23-($T23*M23/12))/$M23)+$Q23)/$J23-R23/M23,0) -> 0 | Y23: =N23*H23/unit -> 0 | Z23: =(P23*H23/unit+Q23*H23/unit)*12 -> 0 | AA23: =IFERROR(DATEDIF(acq,$L23,"m"),0) -> 0 | AC23: WALE
C24: 4 | D24: Office | E24: 공실 | F24: 1385.09 | G24: 683.57 | H24: =F24*py -> 418.98972 | I24: =G24*py -> 206.77993 | J24: =G24/F24 -> 0.49352028 | M24: =DATEDIF(K24,EOMONTH(L24,0),"m") -> 0 | N24: =O24*10 -> 0 | O24: 0 | P24: =O24*(12-T24)/12 -> 0 | Q24: 0 | R24: 0 | S24: 0 | T24: 0 | U24: 0 | V24: 0 | W24: =(($O24+$Q24))/$J24 -> 0 | X24: =IFERROR(((N24*$AE$8/12+$O24*($M24-$S24-($T24*M24/12))/$M24)+$Q24)/$J24-R24/M24,0) -> 0 | Y24: =N24*H24/unit -> 0 | Z24: =(P24*H24/unit+Q24*H24/unit)*12 -> 0 | AA24: =IFERROR(DATEDIF(acq,$L24,"m"),0) -> 0 | AD24: 오피스
C25: 3 | D25: Office | E25: 공실 | F25: 1385.09 | G25: 683.57 | H25: =F25*py -> 418.98972 | I25: =G25*py -> 206.77993 | J25: =G25/F25 -> 0.49352028 | M25: =DATEDIF(K25,EOMONTH(L25,0),"m") -> 0 | N25: =O25*10 -> 0 | O25: 0 | P25: =O25*(12-T25)/12 -> 0 | Q25: 0 | R25: 0 | S25: 0 | T25: 0 | U25: 0 | V25: 0 | W25: =(($O25+$Q25))/$J25 -> 0 | X25: =IFERROR(((N25*$AE$8/12+$O25*($M25-$S25-($T25*M25/12))/$M25)+$Q25)/$J25-R25/M25,0) -> 0 | Y25: =N25*H25/unit -> 0 | Z25: =(P25*H25/unit+Q25*H25/unit)*12 -> 0 | AA25: =IFERROR(DATEDIF(acq,$L25,"m"),0) -> 0 | AD25: 매입시점 | AE25: =SUMPRODUCT(AA11:AA26,F11:F26)/SUM(F11:F26)/12 -> 1.5989583
C26: 2 | D26: Office | E26: 공실 | F26: 1385.09 | G26: 683.57 | H26: =F26*py -> 418.98972 | I26: =G26*py -> 206.77993 | J26: =G26/F26 -> 0.49352028 | M26: =DATEDIF(K26,EOMONTH(L26,0),"m") -> 0 | N26: =O26*10 -> 0 | O26: 0 | P26: =O26*(12-T26)/12 -> 0 | Q26: 0 | R26: 0 | S26: 0 | T26: 0 | U26: 0 | V26: 0 | W26: =(($O26+$Q26))/$J26 -> 0 | X26: =IFERROR(((N26*$AE$8/12+$O26*($M26-$S26-($T26*M26/12))/$M26)+$Q26)/$J26-R26/M26,0) -> 0 | Y26: =N26*H26/unit -> 0 | Z26: =(P26*H26/unit+Q26*H26/unit)*12 -> 0 | AA26: =IFERROR(DATEDIF(acq,$L26,"m"),0) -> 0 | AD26: 매각시점 | AE26: =SUMPRODUCT(AE37:AE51,F37:F51)/SUM(F37:F51)/12 -> 1.7666667
C27: 1 | D27: Retail | E27: 파파 커피앤도넛 | F27: 969.56 | G27: 410.14 | H27: =F27*py -> 293.2919 | I27: =G27*py -> 124.06735 | J27: =G27/F27 -> 0.42301663 | K27: 42064 | L27: 45716 | M27: =DATEDIF(K27,EOMONTH(L27,1),"m") -> 120 | N27: 700000 | O27: 91334 | P27: =O27*(12-T27)/12 -> 83722.833 | Q27: 39143 | R27: 0 | S27: 0 | T27: 1 | U27: 0.03 | V27: 0.03 | W27: =(($O27+$Q27))/$J27 -> 308444.14 | X27: =IFERROR(((N27*$AE$8/12+$O27*($M27-$S27-($T27*M27/12))/$M27)+$Q27)/$J27-R27/M27,0) -> 294588.5 | Y27: =N27*H27/unit -> 205.30433 | Z27: =(P27*H27/unit+Q27*H27/unit)*12 -> 432.42664 | AA27: =IFERROR(DATEDIF(acq,$L27,"m"),0) -> 0 | AD27: 리테일
C28: B101호 | D28: Retail | E28: 퀸즈 샌드위치 | F28: 969.56 | G28: 410.14 | H28: =F28*py -> 293.2919 | I28: =G28*py -> 124.06735 | J28: =G28/F28 -> 0.42301663 | K28: 44926 | L28: 46751 | M28: =DATEDIF(K28,EOMONTH(L28,0),"m") -> 60 | N28: 200000 | O28: 21218 | P28: =O28*(12-T28)/12 -> 17681.667 | Q28: 31827 | R28: 0 | S28: 0 | T28: 2 | U28: 0.03 | V28: 0.03 | W28: =(($O28+$Q28))/$J28 -> 125396.96 | X28: =IFERROR(((N28*$AE$8/12+$O28*($M28-$S28-($T28*M28/12))/$M28)+$Q28)/$J28-R28/M28,0) -> 118219.15 | Y28: =N28*H28/unit -> 58.65838 | Z28: =(P28*H28/unit+Q28*H28/unit)*12 -> 174.24589 | AA28: =IFERROR(DATEDIF(acq,$L28,"m"),0) -> 34 | AD28: 매입시점 | AE28: =SUMPRODUCT(AA27:AA29,F27:F29)/SUM(F27:F29)/12 -> 1.5833333
C29: B102호 | D29: Retail | E29: 로미오 문구점 | F29: 969.56 | G29: 410.14 | H29: =F29*py -> 293.2919 | I29: =G29*py -> 124.06735 | J29: =G29/F29 -> 0.42301663 | K29: 44592 | L29: 46417 | M29: =DATEDIF(K29,EOMONTH(L29,0),"m") -> 60 | N29: 300000 | O29: 31827 | P29: =O29*(12-T29)/12 -> 23870.25 | Q29: 31827 | R29: 0 | S29: 0 | T29: 3 | U29: 0.03 | V29: 0.03 | W29: =(($O29+$Q29))/$J29 -> 150476.36 | X29: =IFERROR(((N29*$AE$8/12+$O29*($M29-$S29-($T29*M29/12))/$M29)+$Q29)/$J29-R29/M29,0) -> 133439.79 | Y29: =N29*H29/unit -> 87.98757 | Z29: =(P29*H29/unit+Q29*H29/unit)*12 -> 196.02663 | AA29: =IFERROR(DATEDIF(acq,$L29,"m"),0) -> 23 | AD29: 매각시점 | AE29: =SUMPRODUCT(AE52:AE60,F52:F60)/SUM(F52:F60)/12 -> 1.2392462
C30: Office Total | F30: =SUMIF($D$11:$D$29,D11,F$11:F$29) -> 22161.44 | G30: =SUMIF($D$11:$D$29,D11,G$11:G$29) -> 10937.12 | H30: =SUMIF($D$11:$D$29,D11,H$11:H$29) -> 6703.8356 | I30: =SUMIF($D$11:$D$29,D11,I$11:I$29) -> 3308.4788 | J30: =G30/F30 -> 0.49352028 | W30: =AVERAGE(W11:W22) -> 285710.15 | X30: =AVERAGE(X11:X22) -> 253938.19 | Y30: =SUMIF($D$11:$D$29,D11,Y$11:Y$29) -> 4566.988 | Z30: =SUMIF($D$11:$D$29,D11,Z$11:Z$29) -> 7424.3324 | AD30: 전체
C31: Retail Total | F31: =SUMIF($D$11:$D$29,$D$29,F$11:F$29) -> 2908.68 | G31: =SUMIF($D$11:$D$29,$D$29,G$11:G$29) -> 1230.42 | H31: =SUMIF($D$11:$D$29,$D$29,H$11:H$29) -> 879.8757 | I31: =SUMIF($D$11:$D$29,$D$29,I$11:I$29) -> 372.20205 | J31: =G31/F31 -> 0.42301663 | Y31: =SUMIF($D$11:$D$29,D29,Y$11:Y$29) -> 351.95028 | Z31: =SUMIF($D$11:$D$29,D29,Z$11:Z$29) -> 802.69916 | AD31: 매입시점 | AE31: =SUMPRODUCT(AA11:AA29,F11:F29)/SUM(F11:F29)/12 -> 1.5971455
C32: Total | F32: =SUM(F30:F31) -> 25070.12 | G32: =SUM(G30:G31) -> 12167.54 | H32: =SUM(H30:H31) -> 7583.7113 | I32: =SUM(I30:I31) -> 3680.6808 | J32: =G32/F32 -> 0.48534032 | Y32: =SUM(Y30:Y31) -> 4918.9383 | Z32: =SUM(Z30:Z31) -> 8227.0316 | AD32: 매각시점 | AE32: =SUMPRODUCT(AE37:AE60,F37:F60)/SUM(F37:F60)/12 -> 1.6763351
C34: 신규 임대차 계약
C35: 층수 | D35: 용도 | E35: 임차인 | F35: 면적 정보(㎡) | H35: 면적 정보(py) | J35: 전용률 | K35: 계약기간 | N35: 임대단가(원/py) | R35: TI (원/py) | S35: Fitout (개월) | T35: Rentfree (개월) | U35: 연상승률 | W35: NOC(원/py) | Y35: 보증금총액 (백만원) | Z35: 계약 유형 | AA35: 계약기간 시작기준일 | AB35: Downtime (개월) | AC35: TI 총액 | AD35: 월세 (원) | AE35: 매각시 잔존월수
F36: 임대면적 | G36: 전용면적 | H36: 임대면적 | I36: 전용면적 | K36: 시작월 | L36: 종료월 | M36: 기간 | N36: 보증금 | O36: 명목 임대료 | P36: 실질 임대료 | Q36: 관리비 | U36: 임대료 | V36: 관리비 | W36: F.NOC | X36: E.NOC
C37: 17 | D37: Office | E37: 리마 상사 | F37: 1385.09 | G37: 683.57 | H37: =F37*py -> 418.98972 | I37: =G37*py -> 206.77993 | J37: =G37/F37 -> 0.49352028 | K37: =EOMONTH($AA37,$AB37) -> 47149 | L37: =EOMONTH($K37,$M37) -> 48975 | M37: 60 | N37: =O37*10 -> 1159274.1 | O37: =(1+$U37)^(DATEDIF(acq,$K37,"y"))*$AE$19 -> 115927.41 | P37: =O37*(12-T37)/12 -> 106266.79 | Q37: =(1+$V37)^(DATEDIF(acq,$K37,"y"))*$AE$20 -> 50647.896 | R37: 0 | S37: 0 | T37: 1 | U37: 0.03 | V37: 0.03 | W37: =(($O37+$Q37))/$J37 -> 337524.74 | X37: =IFERROR(((N37*$AE$8/12+$O37*($M37-$S37-($T37*M37/12))/$M37)+$Q37)/$J37-R37/M37,0) -> 323822.3 | Y37: =N37*H37/unit -> 485.72393 | Z37: 0 | AA37: 47149 | AB37: 0 | AC37: =R37*H37/unit -> 0 | AD37: =O37*H37 -> 48572393 | AE37: =IFERROR(DATEDIF(exit,$L37,"m"),0) -> 48
C38: 16 | D38: Office | E38: 리마 상사 | F38: 1385.09 | G38: 683.57 | H38: =F38*py -> 418.98972 | I38: =G38*py -> 206.77993 | J38: =G38/F38 -> 0.49352028 | K38: =EOMONTH($AA38,$AB38) -> 47149 | L38: =EOMONTH($K38,$M38) -> 48975 | M38: 60 | N38: =O38*10 -> 1159274.1 | O38: =(1+$U38)^(DATEDIF(acq,$K38,"y"))*$AE$19 -> 115927.41 | P38: =O38*(12-T38)/12 -> 106266.79 | Q38: =(1+$V38)^(DATEDIF(acq,$K38,"y"))*$AE$20 -> 50647.896 | R38: 0 | S38: 0 | T38: 1 | U38: 0.03 | V38: 0.03 | W38: =(($O38+$Q38))/$J38 -> 337524.74 | X38: =IFERROR(((N38*$AE$8/12+$O38*($M38-$S38-($T38*M38/12))/$M38)+$Q38)/$J38-R38/M38,0) -> 323822.3 | Y38: =N38*H38/unit -> 485.72393 | Z38: 0 | AA38: 47149 | AB38: 0 | AC38: =R38*H38/unit -> 0 | AD38: =O38*H38 -> 48572393 | AE38: =IFERROR(DATEDIF(exit,$L38,"m"),0) -> 48
C39: 15 | D39: Office | E39: 111퍼센트 | F39: 1385.09 | G39: 683.57 | H39: =F39*py -> 418.98972 | I39: =G39*py -> 206.77993 | J39: =G39/F39 -> 0.49352028 | K39: =EOMONTH($AA39,$AB39) -> 45869 | L39: =EOMONTH($K39,$M39) -> 47695 | M39: 60 | N39: =O39*10 -> 1030000 | O39: =(1+$U39)^(DATEDIF(acq,$K39,"y"))*$AE$19 -> 103000 | P39: =O39*(12-T39)/12 -> 94416.667 | Q39: =(1+$V39)^(DATEDIF(acq,$K39,"y"))*$AE$20 -> 45000 | R39: 0 | S39: 1 | T39: 1 | U39: 0.03 | V39: 0.03 | W39: =(($O39+$Q39))/$J39 -> 299886.36 | X39: =IFERROR(((N39*$AE$8/12+$O39*($M39-$S39-($T39*M39/12))/$M39)+$Q39)/$J39-R39/M39,0) -> 284233.51 | Y39: =N39*H39/unit -> 431.55942 | Z39: 1 | AA39: 45869 | AB39: 0 | AC39: =R39*H39/unit -> 0 | AD39: =O39*H39 -> 43155942 | AE39: =IFERROR(DATEDIF(exit,$L39,"m"),0) -> 6
C40: 14 | D40: Office | E40: 111퍼센트 | F40: 1385.09 | G40: 683.57 | H40: =F40*py -> 418.98972 | I40: =G40*py -> 206.77993 | J40: =G40/F40 -> 0.49352028 | K40: =EOMONTH($AA40,$AB40) -> 45869 | L40: =EOMONTH($K40,$M40) -> 47695 | M40: 60 | N40: =O40*10 -> 1030000 | O40: =(1+$U40)^(DATEDIF(acq,$K40,"y"))*$AE$19 -> 103000 | P40: =O40*(12-T40)/12 -> 94416.667 | Q40: =(1+$V40)^(DATEDIF(acq,$K40,"y"))*$AE$20 -> 45000 | R40: 0 | S40: 1 | T40: 1 | U40: 0.03 | V40: 0.03 | W40: =(($O40+$Q40))/$J40 -> 299886.36 | X40: =IFERROR(((N40*$AE$8/12+$O40*($M40-$S40-($T40*M40/12))/$M40)+$Q40)/$J40-R40/M40,0) -> 284233.51 | Y40: =N40*H40/unit -> 431.55942 | Z40: 1 | AA40: 45869 | AB40: 0 | AC40: =R40*H40/unit -> 0 | AD40: =O40*H40 -> 43155942 | AE40: =IFERROR(DATEDIF(exit,$L40,"m"),0) -> 6
C41: 13 | D41: Office | E41: 111퍼센트 | F41: 1385.09 | G41: 683.57 | H41: =F41*py -> 418.98972 | I41: =G41*py -> 206.77993 | J41: =G41/F41 -> 0.49352028 | K41: =EOMONTH($AA41,$AB41) -> 45869 | L41: =EOMONTH($K41,$M41) -> 47695 | M41: 60 | N41: =O41*10 -> 1030000 | O41: =(1+$U41)^(DATEDIF(acq,$K41,"y"))*$AE$19 -> 103000 | P41: =O41*(12-T41)/12 -> 94416.667 | Q41: =(1+$V41)^(DATEDIF(acq,$K41,"y"))*$AE$20 -> 45000 | R41: 0 | S41: 1 | T41: 1 | U41: 0.03 | V41: 0.03 | W41: =(($O41+$Q41))/$J41 -> 299886.36 | X41: =IFERROR(((N41*$AE$8/12+$O41*($M41-$S41-($T41*M41/12))/$M41)+$Q41)/$J41-R41/M41,0) -> 284233.51 | Y41: =N41*H41/unit -> 431.55942 | Z41: 1 | AA41: 45869 | AB41: 0 | AC41: =R41*H41/unit -> 0 | AD41: =O41*H41 -> 43155942 | AE41: =IFERROR(DATEDIF(exit,$L41,"m"),0) -> 6
C42: 12 | D42: Office | E42: 신라젠 | F42: 1385.09 | G42: 683.57 | H42: =F42*py -> 418.98972 | I42: =G42*py -> 206.77993 | J42: =G42/F42 -> 0.49352028 | K42: =EOMONTH($AA42,$AB42) -> 45869 | L42: =EOMONTH($K42,$M42) -> 47695 | M42: 60 | N42: =O42*10 -> 1030000 | O42: =(1+$U42)^(DATEDIF(acq,$K42,"y"))*$AE$19 -> 103000 | P42: =O42*(12-T42)/12 -> 94416.667 | Q42: =(1+$V42)^(DATEDIF(acq,$K42,"y"))*$AE$20 -> 45000 | R42: 0 | S42: 1 | T42: 1 | U42: 0.03 | V42: 0.03 | W42: =(($O42+$Q42))/$J42 -> 299886.36 | X42: =IFERROR(((N42*$AE$8/12+$O42*($M42-$S42-($T42*M42/12))/$M42)+$Q42)/$J42-R42/M42,0) -> 284233.51 | Y42: =N42*H42/unit -> 431.55942 | Z42: 1 | AA42: 45869 | AB42: 0 | AC42: =R42*H42/unit -> 0 | AD42: =O42*H42 -> 43155942 | AE42: =IFERROR(DATEDIF(exit,$L42,"m"),0) -> 6
C43: 11 | D43: Office | E43: 노벰버 건설 | F43: 1385.09 | G43: 683.57 | H43: =F43*py -> 418.98972 | I43: =G43*py -> 206.77993 | J43: =G43/F43 -> 0.49352028 | K43: =EOMONTH($AA43,$AB43) -> 46904 | L43: =EOMONTH($K43,$M43) -> 48730 | M43: 60 | N43: =O43*10 -> 1125508.8 | O43: =(1+$U43)^(DATEDIF(acq,$K43,"y"))*$AE$19 -> 112550.88 | P43: =O43*(12-T43)/12 -> 103171.64 | Q43: =(1+$V43)^(DATEDIF(acq,$K43,"y"))*$AE$20 -> 49172.715 | R43: 0 | S43: 0 | T43: 1 | U43: 0.03 | V43: 0.03 | W43: =(($O43+$Q43))/$J43 -> 327693.92 | X43: =IFERROR(((N43*$AE$8/12+$O43*($M43-$S43-($T43*M43/12))/$M43)+$Q43)/$J43-R43/M43,0) -> 314390.58 | Y43: =N43*H43/unit -> 471.57663 | Z43: 0 | AA43: 46904 | AB43: 0 | AC43: =R43*H43/unit -> 0 | AD43: =O43*H43 -> 47157663 | AE43: =IFERROR(DATEDIF(exit,$L43,"m"),0) -> 40
...

Sheet Index
B2: Team LAVEL | S2: 변수입력 | T2: 합계1 | U2: 제목
B3: KBC타워 재무모델 | S3: 적정성확인 | T3: 합계2 | U3: 표제목
S4: 오류확인 | T4: 합계3 | U4: 작성자참고
A6: 단위: 백만원
A7: Index
R8: 구분 | S8: 1 | T8: 2 | U8: 3 | V8: 4 | W8: 5 | X8: 6 | Y8: 7 | Z8: 8 | AA8: 9 | AB8: 10 | AC8: 11 | AD8: 12 | AE8: 13 | AF8: 14 | AG8: 15 | AH8: 16
R9: 시작월 | S9: =start -> 45716 | T9: =EOMONTH(S10,1) -> 45900 | U9: =EOMONTH(T10,1) -> 46081 | V9: =EOMONTH(U10,1) -> 46265 | W9: =EOMONTH(V10,1) -> 46446 | X9: =EOMONTH(W10,1) -> 46630 | Y9: =EOMONTH(X10,1) -> 46812 | Z9: =EOMONTH(Y10,1) -> 46996 | AA9: =EOMONTH(Z10,1) -> 47177 | ... AH9: =EOMONTH(AG10,1) -> 48457
R10: 종료월 | S10: =EOMONTH(S9,period-1) -> 45869 | T10: =EOMONTH(T9,period-1) -> 46053 | U10: =EOMONTH(U9,period-1) -> 46234 | V10: =EOMONTH(V9,period-1) -> 46418 | W10: =EOMONTH(W9,period-1) -> 46599 | X10: =EOMONTH(X9,period-1) -> 46783 | Y10: =EOMONTH(Y9,period-1) -> 46965 | Z10: =EOMONTH(Z9,period-1) -> 47149 | ... AH10: =EOMONTH(AH9,period-1) -> 48610
P11: 운영기간Index | R11: =(R14>=[0]!start)*(R14<=[0]!exit)*1 -> 0 | S11: =(S14>=[0]!start)*(S14<=[0]!exit)*1 -> 1 | T11: =(T14>=[0]!start)*(T14<=[0]!exit)*1 -> 1 | U11: =(U14>=[0]!start)*(U14<=[0]!exit)*1 -> 1 | V11: =(V14>=[0]!start)*(V14<=[0]!exit)*1 -> 1 | W11: =(W14>=[0]!start)*(W14<=[0]!exit)*1 -> 1 | X11: =(X14>=[0]!start)*(X14<=[0]!exit)*1 -> 1 | Y11: =(Y14>=[0]!start)*(Y14<=[0]!exit)*1 -> 1 | ... DL11: =(DL14>=[0]!start)*(DL14<=[0]!exit)*1 -> 0
P12: 누적운영기간Index | R12: =SUM($R$11:R11)*R11 -> 0 | S12: =SUM($R$11:S11)*S11 -> 1 | T12: =SUM($R$11:T11)*T11 -> 2 | U12: =SUM($R$11:U11)*U11 -> 3 | V12: =SUM($R$11:V11)*V11 -> 4 | W12: =SUM($R$11:W11)*W11 -> 5 | X12: =SUM($R$11:X11)*X11 -> 6 | Y12: =SUM($R$11:Y11)*Y11 -> 7 | ... DL12: =SUM($R$11:DL11)*DL11 -> 0
P13: 12개월Index | R13: =(MOD(R12,12)=1)*1 -> 0 | S13: =(MOD(S12,12)=1)*1 -> 1 | T13: =(MOD(T12,12)=1)*1 -> 0 | U13: =(MOD(U12,12)=1)*1 -> 0 | V13: =(MOD(V12,12)=1)*1 -> 0 | W13: =(MOD(W12,12)=1)*1 -> 0 | X13: =(MOD(X12,12)=1)*1 -> 0 | Y13: =(MOD(Y12,12)=1)*1 -> 0 | ... DL13: =(MOD(DL12,12)=1)*1 -> 0
P14: Date | R14: =acq -> 45688 | S14: =EOMONTH(R14,1) -> 45716 | T14: =EOMONTH(S14,1) -> 45747 | U14: =EOMONTH(T14,1) -> 45777 | V14: =EOMONTH(U14,1) -> 45808 | W14: =EOMONTH(V14,1) -> 45838 | X14: =EOMONTH(W14,1) -> 45869 | Y14: =EOMONTH(X14,1) -> 45900 | Z14: =EOMONTH(Y14,1) -> 45930 | ... DL14: =EOMONTH(DK14,1) -> 48669
P15: 회계기간 | R15: =SUMIFS($S$8:$AH$8,$S$9:$AH$9,"<="&R$14,$S$10:$AH$10,">="&R$14) -> 0 | S15: =SUMIFS($S$8:$AH$8,$S$9:$AH$9,"<="&S$14,$S$10:$AH$10,">="&S$14) -> 1 | T15: =SUMIFS($S$8:$AH$8,$S$9:$AH$9,"<="&T$14,$S$10:$AH$10,">="&T$14) -> 1 | U15: =SUMIFS($S$8:$AH$8,$S$9:$AH$9,"<="&U$14,$S$10:$AH$10,">="&U$14) -> 1 | V15: =SUMIFS($S$8:$AH$8,$S$9:$AH$9,"<="&V$14,$S$10:$AH$10,">="&V$14) -> 1 | W15: =SUMIFS($S$8:$AH$8,$S$9:$AH$9,"<="&W$14,$S$10:$AH$10,">="&W$14) -> 1 | X15: =SUMIFS($S$8:$AH$8,$S$9:$AH$9,"<="&X$14,$S$10:$AH$10,">="&X$14) -> 1 | Y15: =SUMIFS($S$8:$AH$8,$S$9:$AH$9,"<="&Y$14,$S$10:$AH$10,">="&Y$14) -> 2 | ... DL15: =SUMIFS($S$8:$AH$8,$S$9:$AH$9,"<="&DL$14,$S$10:$AH$10,">="&DL$14) -> 0
P16: 운영년차 | R16: =SUM($R$13:R13)*R11 -> 0 | S16: =SUM($R$13:S13)*S11 -> 1 | T16: =SUM($R$13:T13)*T11 -> 1 | U16: =SUM($R$13:U13)*U11 -> 1 | V16: =SUM($R$13:V13)*V11 -> 1 | W16: =SUM($R$13:W13)*W11 -> 1 | X16: =SUM($R$13:X13)*X11 -> 1 | Y16: =SUM($R$13:Y13)*Y11 -> 1 | ... DL16: =SUM($R$13:DL13)*DL11 -> 0
B17: 현(위) 및 신규(아래) 임대차 계약 | O17: 계약기간 Index | R17: =SUM(R38,R18) -> 0 | S17: =SUM(S38,S18) -> 18 | T17: =SUM(T38,T18) -> 17 | U17: =SUM(U38,U18) -> 21 | V17: =SUM(V38,V18) -> 21 | W17: =SUM(W38,W18) -> 21 | X17: =SUM(X38,X18) -> 23 | Y17: =SUM(Y38,Y18) -> 23 | ... DL17: =SUM(DL38,DL18) -> 0
B18: 층수 | C18: 임차인 | D18: 시작일 | E18: 종료일 | F18: 기간 | G18: 명목 임대료(원) | H18: 실질 임대료(원) | I18: 관리비(원) | J18: 상승률 | K18: 임대면적(㎡) | L18: Fitout | M18: Rentfree | O18: 기존 임대차 | R18: =SUM(R19:R37) -> 0 | S18: =SUM(S19:S37) -> 15 | T18: =SUM(T19:T37) -> 14 | U18: =SUM(U19:U37) -> 14 | V18: =SUM(V19:V37) -> 14 | W18: =SUM(W19:W37) -> 14 | X18: =SUM(X19:X37) -> 14 | Y18: =SUM(Y19:Y37) -> 10 | ... DL18: =SUM(DL19:DL37) -> 0
B19: =Rentroll!$C$11 -> 17 | C19: =VLOOKUP($B19,Rentroll!$C$11:$X$29,3,FALSE) -> 리마 상사 | D19: =VLOOKUP($B19,Rentroll!$C$11:$X$29,9,FALSE) -> 45322 | E19: =VLOOKUP($B19,Rentroll!$C$11:$X$29,10,FALSE) -> 47148 | F19: =VLOOKUP($B19,Rentroll!$C$11:$X$29,11,FALSE) -> 60 | G19: =VLOOKUP($B19,Rentroll!$C$11:$X$29,13,FALSE) -> 100000 | H19: =VLOOKUP($B19,Rentroll!$C$11:$X$29,14,FALSE) -> 75000 | I19: =VLOOKUP($B19,Rentroll!$C$11:$X$29,15,FALSE) -> 45000 | J19: =VLOOKUP($B19,Rentroll!$C$11:$X$29,19,FALSE) -> 0.03 | K19: =VLOOKUP($B19,Rentroll!$C$11:$X$29,4,FALSE) -> 1385.09 | L19: =VLOOKUP($B19,Rentroll!$C$11:$X$29,17,FALSE) -> 0 | M19: =VLOOKUP($B19,Rentroll!$C$11:$X$29,18,FALSE) -> 3 | O19: =B19 -> 17 | R19: =IF(R$14<EOMONTH($E19,1),1,0)*R$11 -> 0 | S19: =IF(S$14<EOMONTH($E19,1),1,0)*S$11 -> 1 | T19: =IF(T$14<EOMONTH($E19,1),1,0)*T$11 -> 1 | U19: =IF(U$14<EOMONTH($E19,1),1,0)*U$11 -> 1 | V19: =IF(V$14<EOMONTH($E19,1),1,0)*V$11 -> 1 | W19: =IF(W$14<EOMONTH($E19,1),1,0)*W$11 -> 1 | X19: =IF(X$14<EOMONTH($E19,1),1,0)*X$11 -> 1 | Y19: =IF(Y$14<EOMONTH($E19,1),1,0)*Y$11 -> 1 | ... DL19: =IF(DL$14<EOMONTH($E19,1),1,0)*DL$11 -> 0
B20: =Rentroll!$C$12 -> 16 | C20: =VLOOKUP($B20,Rentroll!$C$11:$X$29,3,FALSE) -> 리마 상사 | D20: =VLOOKUP($B20,Rentroll!$C$11:$X$29,9,FALSE) -> 45322 | E20: =VLOOKUP($B20,Rentroll!$C$11:$X$29,10,FALSE) -> 47148 | F20: =VLOOKUP($B20,Rentroll!$C$11:$X$29,11,FALSE) -> 60 | G20: =VLOOKUP($B20,Rentroll!$C$11:$X$29,13,FALSE) -> 100000 | H20: =VLOOKUP($B20,Rentroll!$C$11:$X$29,14,FALSE) -> 75000 | I20: =VLOOKUP($B20,Rentroll!$C$11:$X$29,15,FALSE) -> 45000 | J20: =VLOOKUP($B20,Rentroll!$C$11:$X$29,19,FALSE) -> 0.03 | K20: =VLOOKUP($B20,Rentroll!$C$11:$X$29,4,FALSE) -> 1385.09 | L20: =VLOOKUP($B20,Rentroll!$C$11:$X$29,17,FALSE) -> 0 | M20: =VLOOKUP($B20,Rentroll!$C$11:$X$29,18,FALSE) -> 3 | O20: =B20 -> 16 | R20: =IF(R$14<EOMONTH($E20,1),1,0)*R$11 -> 0 | S20: =IF(S$14<EOMONTH($E20,1),1,0)*S$11 -> 1 | T20: =IF(T$14<EOMONTH($E20,1),1,0)*T$11 -> 1 | U20: =IF(U$14<EOMONTH($E20,1),1,0)*U$11 -> 1 | V20: =IF(V$14<EOMONTH($E20,1),1,0)*V$11 -> 1 | W20: =IF(W$14<EOMONTH($E20,1),1,0)*W$11 -> 1 | X20: =IF(X$14<EOMONTH($E20,1),1,0)*X$11 -> 1 | Y20: =IF(Y$14<EOMONTH($E20,1),1,0)*Y$11 -> 1 | ... DL20: =IF(DL$14<EOMONTH($E20,1),1,0)*DL$11 -> 0
B21: =Rentroll!$C$13 -> 15 | C21: =VLOOKUP($B21,Rentroll!$C$11:$X$29,3,FALSE) -> 모빌리티 테크놀로지 | D21: =VLOOKUP($B21,Rentroll!$C$11:$X$29,9,FALSE) -> 44042 | E21: =VLOOKUP($B21,Rentroll!$C$11:$X$29,10,FALSE) -> 45869 | F21: =VLOOKUP($B21,Rentroll!$C$11:$X$29,11,FALSE) -> 60 | G21: =VLOOKUP($B21,Rentroll!$C$11:$X$29,13,FALSE) -> 90041 | H21: =VLOOKUP($B21,Rentroll!$C$11:$X$29,14,FALSE) -> 67530.75 | I21: =VLOOKUP($B21,Rentroll!$C$11:$X$29,15,FALSE) -> 45020 | J21: =VLOOKUP($B21,Rentroll!$C$11:$X$29,19,FALSE) -> 0.03 | K21: =VLOOKUP($B21,Rentroll!$C$11:$X$29,4,FALSE) -> 1385.09 | L21: =VLOOKUP($B21,Rentroll!$C$11:$X$29,17,FALSE) -> 0 | M21: =VLOOKUP($B21,Rentroll!$C$11:$X$29,18,FALSE) -> 3 | O21: =B21 -> 15 | R21: =IF(R$14<EOMONTH($E21,1),1,0)*R$11 -> 0 | S21: =IF(S$14<EOMONTH($E21,1),1,0)*S$11 -> 1 | T21: =IF(T$14<EOMONTH($E21,1),1,0)*T$11 -> 1 | U21: =IF(U$14<EOMONTH($E21,1),1,0)*U$11 -> 1 | V21: =IF(V$14<EOMONTH($E21,1),1,0)*V$11 -> 1 | W21: =IF(W$14<EOMONTH($E21,1),1,0)*W$11 -> 1 | X21: =IF(X$14<EOMONTH($E21,1),1,0)*X$11 -> 1 | Y21: =IF(Y$14<EOMONTH($E21,1),1,0)*Y$11 -> 0 | ... DL21: =IF(DL$14<EOMONTH($E21,1),1,0)*DL$11 -> 0
B22: =Rentroll!$C$14 -> 14 | C22: =VLOOKUP($B22,Rentroll!$C$11:$X$29,3,FALSE) -> 모빌리티 테크놀로지 | D22: =VLOOKUP($B22,Rentroll!$C$11:$X$29,9,FALSE) -> 44043 | E22: =VLOOKUP($B22,Rentroll!$C$11:$X$29,10,FALSE) -> 45868 | F22: =VLOOKUP($B22,Rentroll!$C$11:$X$29,11,FALSE) -> 60 | G22: =VLOOKUP($B22,Rentroll!$C$11:$X$29,13,FALSE) -> 90041 | H22: =VLOOKUP($B22,Rentroll!$C$11:$X$29,14,FALSE) -> 67530.75 | I22: =VLOOKUP($B22,Rentroll!$C$11:$X$29,15,FALSE) -> 45020 | J22: =VLOOKUP($B22,Rentroll!$C$11:$X$29,19,FALSE) -> 0.03 | K22: =VLOOKUP($B22,Rentroll!$C$11:$X$29,4,FALSE) -> 1385.09 | L22: =VLOOKUP($B22,Rentroll!$C$11:$X$29,17,FALSE) -> 0 | M22: =VLOOKUP($B22,Rentroll!$C$11:$X$29,18,FALSE) -> 3 | O22: =B22 -> 14 | R22: =IF(R$14<EOMONTH($E22,1),1,0)*R$11 -> 0 | S22: =IF(S$14<EOMONTH($E22,1),1,0)*S$11 -> 1 | T22: =IF(T$14<EOMONTH($E22,1),1,0)*T$11 -> 1 | U22: =IF(U$14<EOMONTH($E22,1),1,0)*U$11 -> 1 | V22: =IF(V$14<EOMONTH($E22,1),1,0)*V$11 -> 1 | W22: =IF(W$14<EOMONTH($E22,1),1,0)*W$11 -> 1 | X22: =IF(X$14<EOMONTH($E22,1),1,0)*X$11 -> 1 | Y22: =IF(Y$14<EOMONTH($E22,1),1,0)*Y$11 -> 0 | ... DL22: =IF(DL$14<EOMONTH($E22,1),1,0)*DL$11 -> 0
B23: =Rentroll!$C$15 -> 13 | C23: =VLOOKUP($B23,Rentroll!$C$11:$X$29,3,FALSE) -> 모빌리티 테크놀로지 | D23: =VLOOKUP($B23,Rentroll!$C$11:$X$29,9,FALSE) -> 44043 | E23: =VLOOKUP($B23,Rentroll!$C$11:$X$29,10,FALSE) -> 45868 | F23: =VLOOKUP($B23,Rentroll!$C$11:$X$29,11,FALSE) -> 60 | G23: =VLOOKUP($B23,Rentroll!$C$11:$X$29,13,FALSE) -> 90041 | H23: =VLOOKUP($B23,Rentroll!$C$11:$X$29,14,FALSE) -> 67530.75 | I23: =VLOOKUP($B23,Rentroll!$C$11:$X$29,15,FALSE) -> 45020 | J23: =VLOOKUP($B23,Rentroll!$C$11:$X$29,19,FALSE) -> 0.03 | K23: =VLOOKUP($B23,Rentroll!$C$11:$X$29,4,FALSE) -> 1385.09 | L23: =VLOOKUP($B23,Rentroll!$C$11:$X$29,17,FALSE) -> 0 | M23: =VLOOKUP($B23,Rentroll!$C$11:$X$29,18,FALSE) -> 3 | O23: =B23 -> 13 | R23: =IF(R$14<EOMONTH($E23,1),1,0)*R$11 -> 0 | S23: =IF(S$14<EOMONTH($E23,1),1,0)*S$11 -> 1 | T23: =IF(T$14<EOMONTH($E23,1),1,0)*T$11 -> 1 | U23: =IF(U$14<EOMONTH($E23,1),1,0)*U$11 -> 1 | V23: =IF(V$14<EOMONTH($E23,1),1,0)*V$11 -> 1 | W23: =IF(W$14<EOMONTH($E23,1),1,0)*W$11 -> 1 | X23: =IF(X$14<EOMONTH($E23,1),1,0)*X$11 -> 1 | Y23: =IF(Y$14<EOMONTH($E23,1),1,0)*Y$11 -> 0 | ... DL23: =IF(DL$14<EOMONTH($E23,1),1,0)*DL$11 -> 0
B24: =Rentroll!$C$16 -> 12 | C24: =VLOOKUP($B24,Rentroll!$C$11:$X$29,3,FALSE) -> 모빌리티 테크놀로지 | D24: =VLOOKUP($B24,Rentroll!$C$11:$X$29,9,FALSE) -> 44043 | E24: =VLOOKUP($B24,Rentroll!$C$11:$X$29,10,FALSE) -> 45868 | F24: =VLOOKUP($B24,Rentroll!$C$11:$X$29,11,FALSE) -> 60 | G24: =VLOOKUP($B24,Rentroll!$C$11:$X$29,13,FALSE) -> 90041 | H24: =VLOOKUP($B24,Rentroll!$C$11:$X$29,14,FALSE) -> 67530.75 | I24: =VLOOKUP($B24,Rentroll!$C$11:$X$29,15,FALSE) -> 45020 | J24: =VLOOKUP($B24,Rentroll!$C$11:$X$29,19,FALSE) -> 0.03 | K24: =VLOOKUP($B24,Rentroll!$C$11:$X$29,4,FALSE) -> 1385.09 | L24: =VLOOKUP($B24,Rentroll!$C$11:$X$29,17,FALSE) -> 0 | M24: =VLOOKUP($B24,Rentroll!$C$11:$X$29,18,FALSE) -> 3 | O24: =B24 -> 12 | R24: =IF(R$14<EOMONTH($E24,1),1,0)*R$11 -> 0 | S24: =IF(S$14<EOMONTH($E24,1),1,0)*S$11 -> 1 | T24: =IF(T$14<EOMONTH($E24,1),1,0)*T$11 -> 1 | U24: =IF(U$14<EOMONTH($E24,1),1,0)*U$11 -> 1 | V24: =IF(V$14<EOMONTH($E24,1),1,0)*V$11 -> 1 | W24: =IF(W$14<EOMONTH($E24,1),1,0)*W$11 -> 1 | X24: =IF(X$14<EOMONTH($E24,1),1,0)*X$11 -> 1 | Y24: =IF(Y$14<EOMONTH($E24,1),1,0)*Y$11 -> 0 | ... DL24: =IF(DL$14<EOMONTH($E24,1),1,0)*DL$11 -> 0
B25: =Rentroll!$C$17 -> 11 | C25: =VLOOKUP($B25,Rentroll!$C$11:$X$29,3,FALSE) -> 노벰버 건설 | D25: =VLOOKUP($B25,Rentroll!$C$11:$X$29,9,FALSE) -> 45077 | E25: =VLOOKUP($B25,Rentroll!$C$11:$X$29,10,FALSE) -> 46903 | F25: =VLOOKUP($B25,Rentroll!$C$11:$X$29,11,FALSE) -> 60 | G25: =VLOOKUP($B25,Rentroll!$C$11:$X$29,13,FALSE) -> 103000 | H25: =VLOOKUP($B25,Rentroll!$C$11:$X$29,14,FALSE) -> 85833.333 | I25: =VLOOKUP($B25,Rentroll!$C$11:$X$29,15,FALSE) -> 46350 | J25: =VLOOKUP($B25,Rentroll!$C$11:$X$29,19,FALSE) -> 0.03 | K25: =VLOOKUP($B25,Rentroll!$C$11:$X$29,4,FALSE) -> 1385.09 | L25: =VLOOKUP($B25,Rentroll!$C$11:$X$29,17,FALSE) -> 0 | M25: =VLOOKUP($B25,Rentroll!$C$11:$X$29,18,FALSE) -> 2 | O25: =B25 -> 11 | R25: =IF(R$14<EOMONTH($E25,1),1,0)*R$11 -> 0 | S25: =IF(S$14<EOMONTH($E25,1),1,0)*S$11 -> 1 | T25: =IF(T$14<EOMONTH($E25,1),1,0)*T$11 -> 1 | U25: =IF(U$14<EOMONTH($E25,1),1,0)*U$11 -> 1 | V25: =IF(V$14<EOMONTH($E25,1),1,0)*V$11 -> 1 | W25: =IF(W$14<EOMONTH($E25,1),1,0)*W$11 -> 1 | X25: =IF(X$14<EOMONTH($E25,1),1,0)*X$11 -> 1 | Y25: =IF(Y$14<EOMONTH($E25,1),1,0)*Y$11 -> 1 | ... DL25: =IF(DL$14<EOMONTH($E25,1),1,0)*DL$11 -> 0
B26: =Rentroll!$C$18 -> 10 | C26: =VLOOKUP($B26,Rentroll!$C$11:$X$29,3,FALSE) -> 노벰버 건설 | D26: =VLOOKUP($B26,Rentroll!$C$11:$X$29,9,FALSE) -> 45077 | E26: =VLOOKUP($B26,Rentroll!$C$11:$X$29,10,FALSE) -> 46903 | F26: =VLOOKUP($B26,Rentroll!$C$11:$X$29,11,FALSE) -> 60 | G26: =VLOOKUP($B26,Rentroll!$C$11:$X$29,13,FALSE) -> 103000 | H26: =VLOOKUP($B26,Rentroll!$C$11:$X$29,14,FALSE) -> 85833.333 | I26: =VLOOKUP($B26,Rentroll!$C$11:$X$29,15,FALSE) -> 46350 | J26: =VLOOKUP($B26,Rentroll!$C$11:$X$29,19,FALSE) -> 0.03 | K26: =VLOOKUP($B26,Rentroll!$C$11:$X$29,4,FALSE) -> 1385.09 | L26: =VLOOKUP($B26,Rentroll!$C$11:$X$29,17,FALSE) -> 0 | M26: =VLOOKUP($B26,Rentroll!$C$11:$X$29,18,FALSE) -> 2 | O26: =B26 -> 10 | R26: =IF(R$14<EOMONTH($E26,1),1,0)*R$11 -> 0 | S26: =IF(S$14<EOMONTH($E26,1),1,0)*S$11 -> 1 | T26: =IF(T$14<EOMONTH($E26,1),1,0)*T$11 -> 1 | U26: =IF(U$14<EOMONTH($E26,1),1,0)*U$11 -> 1 | V26: =IF(V$14<EOMONTH($E26,1),1,0)*V$11 -> 1 | W26: =IF(W$14<EOMONTH($E26,1),1,0)*W$11 -> 1 | X26: =IF(X$14<EOMONTH($E26,1),1,0)*X$11 -> 1 | Y26: =IF(Y$14<EOMONTH($E26,1),1,0)*Y$11 -> 1 | ... DL26: =IF(DL$14<EOMONTH($E26,1),1,0)*DL$11 -> 0
B27: =Rentroll!$C$19 -> 9 | C27: =VLOOKUP($B27,Rentroll!$C$11:$X$29,3,FALSE) -> 노벰버 건설 | D27: =VLOOKUP($B27,Rentroll!$C$11:$X$29,9,FALSE) -> 45077 | E27: =VLOOKUP($B27,Rentroll!$C$11:$X$29,10,FALSE) -> 46903 | F27: =VLOOKUP($B27,Rentroll!$C$11:$X$29,11,FALSE) -> 60 | G27: =VLOOKUP($B27,Rentroll!$C$11:$X$29,13,FALSE) -> 103000 | H27: =VLOOKUP($B27,Rentroll!$C$11:$X$29,14,FALSE) -> 85833.333 | I27: =VLOOKUP($B27,Rentroll!$C$11:$X$29,15,FALSE) -> 46350 | J27: =VLOOKUP($B27,Rentroll!$C$11:$X$29,19,FALSE) -> 0.03 | K27: =VLOOKUP($B27,Rentroll!$C$11:$X$29,4,FALSE) -> 1385.09 | L27: =VLOOKUP($B27,Rentroll!$C$11:$X$29,17,FALSE) -> 0 | M27: =VLOOKUP($B27,Rentroll!$C$11:$X$29,18,FALSE) -> 2 | O27: =B27 -> 9 | R27: =IF(R$14<EOMONTH($E27,1),1,0)*R$11 -> 0 | S27: =IF(S$14<EOMONTH($E27,1),1,0)*S$11 -> 1 | T27: =IF(T$14<EOMONTH($E27,1),1,0)*T$11 -> 1 | U27: =IF(U$14<EOMONTH($E27,1),1,0)*U$11 -> 1 | V27: =IF(V$14<EOMONTH($E27,1),1,0)*V$11 -> 1 | W27: =IF(W$14<EOMONTH($E27,1),1,0)*W$11 -> 1 | X27: =IF(X$14<EOMONTH($E27,1),1,0)*X$11 -> 1 | Y27: =IF(Y$14<EOMONTH($E27,1),1,0)*Y$11 -> 1 | ... DL27: =IF(DL$14<EOMONTH($E27,1),1,0)*DL$11 -> 0
B28: =Rentroll!$C$20 -> 8 | C28: =VLOOKUP($B28,Rentroll!$C$11:$X$29,3,FALSE) -> 오토 커머셜 | D28: =VLOOKUP($B28,Rentroll!$C$11:$X$29,9,FALSE) -> 44651 | E28: =VLOOKUP($B28,Rentroll!$C$11:$X$29,10,FALSE) -> 46476 | F28: =VLOOKUP($B28,Rentroll!$C$11:$X$29,11,FALSE) -> 60 | G28: =VLOOKUP($B28,Rentroll!$C$11:$X$29,13,FALSE) -> 95481 | H28: =VLOOKUP($B28,Rentroll!$C$11:$X$29,14,FALSE) -> 87524.25 | I28: =VLOOKUP($B28,Rentroll!$C$11:$X$29,15,FALSE) -> 42436 | J28: =VLOOKUP($B28,Rentroll!$C$11:$X$29,19,FALSE) -> 0.03 | K28: =VLOOKUP($B28,Rentroll!$C$11:$X$29,4,FALSE) -> 1385.09 | L28: =VLOOKUP($B28,Rentroll!$C$11:$X$29,17,FALSE) -> 0 | M28: =VLOOKUP($B28,Rentroll!$C$11:$X$29,18,FALSE) -> 1 | O28: =B28 -> 8 | R28: =IF(R$14<EOMONTH($E28,1),1,0)*R$11 -> 0 | S28: =IF(S$14<EOMONTH($E28,1),1,0)*S$11 -> 1 | T28: =IF(T$14<EOMONTH($E28,1),1,0)*T$11 -> 1 | U28: =IF(U$14<EOMONTH($E28,1),1,0)*U$11 -> 1 | V28: =IF(V$14<EOMONTH($E28,1),1,0)*V$11 -> 1 | W28: =IF(W$14<EOMONTH($E28,1),1,0)*W$11 -> 1 | X28: =IF(X$14<EOMONTH($E28,1),1,0)*X$11 -> 1 | Y28: =IF(Y$14<EOMONTH($E28,1),1,0)*Y$11 -> 1 | ... DL28: =IF(DL$14<EOMONTH($E28,1),1,0)*DL$11 -> 0
B29: =Rentroll!$C$21 -> 7 | C29: =VLOOKUP($B29,Rentroll!$C$11:$X$29,3,FALSE) -> 오토 커머셜 | D29: =VLOOKUP($B29,Rentroll!$C$11:$X$29,9,FALSE) -> 44651 | E29: =VLOOKUP($B29,Rentroll!$C$11:$X$29,10,FALSE) -> 46476 | F29: =VLOOKUP($B29,Rentroll!$C$11:$X$29,11,FALSE) -> 60 | G29: =VLOOKUP($B29,Rentroll!$C$11:$X$29,13,FALSE) -> 95481 | H29: =VLOOKUP($B29,Rentroll!$C$11:$X$29,14,FALSE) -> 87524.25 | I29: =VLOOKUP($B29,Rentroll!$C$11:$X$29,15,FALSE) -> 42436 | J29: =VLOOKUP($B29,Rentroll!$C$11:$X$29,19,FALSE) -> 0.03 | K29: =VLOOKUP($B29,Rentroll!$C$11:$X$29,4,FALSE) -> 1385.09 | L29: =VLOOKUP($B29,Rentroll!$C$11:$X$29,17,FALSE) -> 0 | M29: =VLOOKUP($B29,Rentroll!$C$11:$X$29,18,FALSE) -> 1 | O29: =B29 -> 7 | R29: =IF(R$14<EOMONTH($E29,1),1,0)*R$11 -> 0 | S29: =IF(S$14<EOMONTH($E29,1),1,0)*S$11 -> 1 | T29: =IF(T$14<EOMONTH($E29,1),1,0)*T$11 -> 1 | U29: =IF(U$14<EOMONTH($E29,1),1,0)*U$11 -> 1 | V29: =IF(V$14<EOMONTH($E29,1),1,0)*V$11 -> 1 | W29: =IF(W$14<EOMONTH($E29,1),1,0)*W$11 -> 1 | X29: =IF(X$14<EOMONTH($E29,1),1,0)*X$11 -> 1 | Y29: =IF(Y$14<EOMONTH($E29,1),1,0)*Y$11 -> 1 | ... DL29: =IF(DL$14<EOMONTH($E29,1),1,0)*DL$11 -> 0
B30: =Rentroll!$C$22 -> 6 | C30: =VLOOKUP($B30,Rentroll!$C$11:$X$29,3,FALSE) -> 오토 커머셜 | D30: =VLOOKUP($B30,Rentroll!$C$11:$X$29,9,FALSE) -> 44651 | E30: =VLOOKUP($B30,Rentroll!$C$11:$X$29,10,FALSE) -> 46476 | F30: =VLOOKUP($B30,Rentroll!$C$11:$X$29,11,FALSE) -> 60 | G30: =VLOOKUP($B30,Rentroll!$C$11:$X$29,13,FALSE) -> 95481 | H30: =VLOOKUP($B30,Rentroll!$C$11:$X$29,14,FALSE) -> 87524.25 | I30: =VLOOKUP($B30,Rentroll!$C$11:$X$29,15,FALSE) -> 42436 | J30: =VLOOKUP($B30,Rentroll!$C$11:$X$29,19,FALSE) -> 0.03 | K30: =VLOOKUP($B30,Rentroll!$C$11:$X$29,4,FALSE) -> 1385.09 | L30: =VLOOKUP($B30,Rentroll!$C$11:$X$29,17,FALSE) -> 0 | M30: =VLOOKUP($B30,Rentroll!$C$11:$X$29,18,FALSE) -> 1 | O30: =B30 -> 6 | R30: =IF(R$14<EOMONTH($E30,1),1,0)*R$11 -> 0 | S30: =IF(S$14<EOMONTH($E30,1),1,0)*S$11 -> 1 | T30: =IF(T$14<EOMONTH($E30,1),1,0)*T$11 -> 1 | U30: =IF(U$14<EOMONTH($E30,1),1,0)*U$11 -> 1 | V30: =IF(V$14<EOMONTH($E30,1),1,0)*V$11 -> 1 | W30: =IF(W$14<EOMONTH($E30,1),1,0)*W$11 -> 1 | X30: =IF(X$14<EOMONTH($E30,1),1,0)*X$11 -> 1 | Y30: =IF(Y$14<EOMONTH($E30,1),1,0)*Y$11 -> 1 | ... DL30: =IF(DL$14<EOMONTH($E30,1),1,0)*DL$11 -> 0
B31: =Rentroll!$C$23 -> 5 | C31: =VLOOKUP($B31,Rentroll!$C$11:$X$29,3,FALSE) -> 공실 | F31: =VLOOKUP($B31,Rentroll!$C$11:$X$29,11,FALSE) -> 0 | G31: =VLOOKUP($B31,Rentroll!$C$11:$X$29,13,FALSE) -> 0 | H31: =VLOOKUP($B31,Rentroll!$C$11:$X$29,14,FALSE) -> 0 | I31: =VLOOKUP($B31,Rentroll!$C$11:$X$29,15,FALSE) -> 0 | J31: =VLOOKUP($B31,Rentroll!$C$11:$X$29,19,FALSE) -> 0 | K31: =VLOOKUP($B31,Rentroll!$C$11:$X$29,4,FALSE) -> 1385.09 | L31: =VLOOKUP($B31,Rentroll!$C$11:$X$29,17,FALSE) -> 0 | M31: =VLOOKUP($B31,Rentroll!$C$11:$X$29,18,FALSE) -> 0 | O31: =B31 -> 5 | R31: =IF(R$14<EOMONTH($E31,1),1,0)*R$11 -> 0 | S31: =IF(S$14<EOMONTH($E31,1),1,0)*S$11 -> 0 | T31: =IF(T$14<EOMONTH($E31,1),1,0)*T$11 -> 0 | U31: =IF(U$14<EOMONTH($E31,1),1,0)*U$11 -> 0 | V31: =IF(V$14<EOMONTH($E31,1),1,0)*V$11 -> 0 | W31: =IF(W$14<EOMONTH($E31,1),1,0)*W$11 -> 0 | X31: =IF(X$14<EOMONTH($E31,1),1,0)*X$11 -> 0 | Y31: =IF(Y$14<EOMONTH($E31,1),1,0)*Y$11 -> 0 | ... DL31: =IF(DL$14<EOMONTH($E31,1),1,0)*DL$11 -> 0
B32: =Rentroll!$C$24 -> 4 | C32: =VLOOKUP($B32,Rentroll!$C$11:$X$29,3,FALSE) -> 공실 | F32: =VLOOKUP($B32,Rentroll!$C$11:$X$29,11,FALSE) -> 0 | G32: =VLOOKUP($B32,Rentroll!$C$11:$X$29,13,FALSE) -> 0 | H32: =VLOOKUP($B32,Rentroll!$C$11:$X$29,14,FALSE) -> 0 | I32: =VLOOKUP($B32,Rentroll!$C$11:$X$29,15,FALSE) -> 0 | J32: =VLOOKUP($B32,Rentroll!$C$11:$X$29,19,FALSE) -> 0 | K32: =VLOOKUP($B32,Rentroll!$C$11:$X$29,4,FALSE) -> 1385.09 | L32: =VLOOKUP($B32,Rentroll!$C$11:$X$29,17,FALSE) -> 0 | M32: =VLOOKUP($B32,Rentroll!$C$11:$X$29,18,FALSE) -> 0 | O32: =B32 -> 4 | R32: =IF(R$14<EOMONTH($E32,1),1,0)*R$11 -> 0 | S32: =IF(S$14<EOMONTH($E32,1),1,0)*S$11 -> 0 | T32: =IF(T$14<EOMONTH($E32,1),1,0)*T$11 -> 0 | U32: =IF(U$14<EOMONTH($E32,1),1,0)*U$11 -> 0 | V32: =IF(V$14<EOMONTH($E32,1),1,0)*V$11 -> 0 | W32: =IF(W$14<EOMONTH($E32,1),1,0)*W$11 -> 0 | X32: =IF(X$14<EOMONTH($E32,1),1,0)*X$11 -> 0 | Y32: =IF(Y$14<EOMONTH($E32,1),1,0)*Y$11 -> 0 | ... DL32: =IF(DL$14<EOMONTH($E32,1),1,0)*DL$11 -> 0
B33: =Rentroll!$C$25 -> 3 | C33: =VLOOKUP($B33,Rentroll!$C$11:$X$29,3,FALSE) -> 공실 | F33: =VLOOKUP($B33,Rentroll!$C$11:$X$29,11,FALSE) -> 0 | G33: =VLOOKUP($B33,Rentroll!$C$11:$X$29,13,FALSE) -> 0 | H33: =VLOOKUP($B33,Rentroll!$C$11:$X$29,14,FALSE) -> 0 | I33: =VLOOKUP($B33,Rentroll!$C$11:$X$29,15,FALSE) -> 0 | J33: =VLOOKUP($B33,Rentroll!$C$11:$X$29,19,FALSE) -> 0 | K33: =VLOOKUP($B33,Rentroll!$C$11:$X$29,4,FALSE) -> 1385.09 | L33: =VLOOKUP($B33,Rentroll!$C$11:$X$29,17,FALSE) -> 0 | M33: =VLOOKUP($B33,Rentroll!$C$11:$X$29,18,FALSE) -> 0 | O33: =B33 -> 3 | R33: =IF(R$14<EOMONTH($E33,1),1,0)*R$11 -> 0 | S33: =IF(S$14<EOMONTH($E33,1),1,0)*S$11 -> 0 | T33: =IF(T$14<EOMONTH($E33,1),1,0)*T$11 -> 0 | U33: =IF(U$14<EOMONTH($E33,1),1,0)*U$11 -> 0 | V33: =IF(V$14<EOMONTH($E33,1),1,0)*V$11 -> 0 | W33: =IF(W$14<EOMONTH($E33,1),1,0)*W$11 -> 0 | X33: =IF(X$14<EOMONTH($E33,1),1,0)*X$11 -> 0 | Y33: =IF(Y$14<EOMONTH($E33,1),1,0)*Y$11 -> 0 | ... DL33: =IF(DL$14<EOMONTH($E33,1),1,0)*DL$11 -> 0
B34: =Rentroll!$C$26 -> 2 | C34: =VLOOKUP($B34,Rentroll!$C$11:$X$29,3,FALSE) -> 공실 | F34: =VLOOKUP($B34,Rentroll!$C$11:$X$29,11,FALSE) -> 0 | G34: =VLOOKUP($B34,Rentroll!$C$11:$X$29,13,FALSE) -> 0 | H34: =VLOOKUP($B34,Rentroll!$C$11:$X$29,14,FALSE) -> 0 | I34: =VLOOKUP($B34,Rentroll!$C$11:$X$29,15,FALSE) -> 0 | J34: =VLOOKUP($B34,Rentroll!$C$11:$X$29,19,FALSE) -> 0 | K34: =VLOOKUP($B34,Rentroll!$C$11:$X$29,4,FALSE) -> 1385.09 | L34: =VLOOKUP($B34,Rentroll!$C$11:$X$29,17,FALSE) -> 0 | M34: =VLOOKUP($B34,Rentroll!$C$11:$X$29,18,FALSE) -> 0 | O34: =B34 -> 2 | R34: =IF(R$14<EOMONTH($E34,1),1,0)*R$11 -> 0 | S34: =IF(S$14<EOMONTH($E34,1),1,0)*S$11 -> 0 | T34: =IF(T$14<EOMONTH($E34,1),1,0)*T$11 -> 0 | U34: =IF(U$14<EOMONTH($E34,1),1,0)*U$11 -> 0 | V34: =IF(V$14<EOMONTH($E34,1),1,0)*V$11 -> 0 | W34: =IF(W$14<EOMONTH($E34,1),1,0)*W$11 -> 0 | X34: =IF(X$14<EOMONTH($E34,1),1,0)*X$11 -> 0 | Y34: =IF(Y$14<EOMONTH($E34,1),1,0)*Y$11 -> 0 | ... DL34: =IF(DL$14<EOMONTH($E34,1),1,0)*DL$11 -> 0
B35: =Rentroll!$C$27 -> 1 | C35: =VLOOKUP($B35,Rentroll!$C$11:$X$29,3,FALSE) -> 파파 커피앤도넛 | D35: =VLOOKUP($B35,Rentroll!$C$11:$X$29,9,FALSE) -> 42064 | E35: =VLOOKUP($B35,Rentroll!$C$11:$X$29,10,FALSE) -> 45716 | F35: =VLOOKUP($B35,Rentroll!$C$11:$X$29,11,FALSE) -> 120 | G35: =VLOOKUP($B35,Rentroll!$C$11:$X$29,13,FALSE) -> 91334 | H35: =VLOOKUP($B35,Rentroll!$C$11:$X$29,14,FALSE) -> 83722.833 | I35: =VLOOKUP($B35,Rentroll!$C$11:$X$29,15,FALSE) -> 39143 | J35: =VLOOKUP($B35,Rentroll!$C$11:$X$29,19,FALSE) -> 0.03 | K35: =VLOOKUP($B35,Rentroll!$C$11:$X$29,4,FALSE) -> 969.56 | L35: =VLOOKUP($B35,Rentroll!$C$11:$X$29,17,FALSE) -> 0 | M35: =VLOOKUP($B35,Rentroll!$C$11:$X$29,18,FALSE) -> 1 | O35: =B35 -> 1 | R35: =IF(R$14<EOMONTH($E35,1),1,0)*R$11 -> 0 | S35: =IF(S$14<EOMONTH($E35,1),1,0)*S$11 -> 1 | T35: =IF(T$14<EOMONTH($E35,1),1,0)*T$11 -> 0 | U35: =IF(U$14<EOMONTH($E35,1),1,0)*U$11 -> 0 | V35: =IF(V$14<EOMONTH($E35,1),1,0)*V$11 -> 0 | W35: =IF(W$14<EOMONTH($E35,1),1,0)*W$11 -> 0 | X35: =IF(X$14<EOMONTH($E35,1),1,0)*X$11 -> 0 | Y35: =IF(Y$14<EOMONTH($E35,1),1,0)*Y$11 -> 0 | ... DL35: =IF(DL$14<EOMONTH($E35,1),1,0)*DL$11 -> 0
B36: =Rentroll!$C$28 -> B101호 | C36: =VLOOKUP($B36,Rentroll!$C$11:$X$29,3,FALSE) -> 퀸즈 샌드위치 | D36: =VLOOKUP($B36,Rentroll!$C$11:$X$29,9,FALSE) -> 44926 | E36: =VLOOKUP($B36,Rentroll!$C$11:$X$29,10,FALSE) -> 46751 | F36: =VLOOKUP($B36,Rentroll!$C$11:$X$29,11,FALSE) -> 60 | G36: =VLOOKUP($B36,Rentroll!$C$11:$X$29,13,FALSE) -> 21218 | H36: =VLOOKUP($B36,Rentroll!$C$11:$X$29,14,FALSE) -> 17681.667 | I36: =VLOOKUP($B36,Rentroll!$C$11:$X$29,15,FALSE) -> 31827 | J36: =VLOOKUP($B36,Rentroll!$C$11:$X$29,19,FALSE) -> 0.03 | K36: =VLOOKUP($B36,Rentroll!$C$11:$X$29,4,FALSE) -> 969.56 | L36: =VLOOKUP($B36,Rentroll!$C$11:$X$29,17,FALSE) -> 0 | M36: =VLOOKUP($B36,Rentroll!$C$11:$X$29,18,FALSE) -> 2 | O36: =B36 -> B101호 | R36: =IF(R$14<EOMONTH($E36,1),1,0)*R$11 -> 0 | S36: =IF(S$14<EOMONTH($E36,1),1,0)*S$11 -> 1 | T36: =IF(T$14<EOMONTH($E36,1),1,0)*T$11 -> 1 | U36: =IF(U$14<EOMONTH($E36,1),1,0)*U$11 -> 1 | V36: =IF(V$14<EOMONTH($E36,1),1,0)*V$11 -> 1 | W36: =IF(W$14<EOMONTH($E36,1),1,0)*W$11 -> 1 | X36: =IF(X$14<EOMONTH($E36,1),1,0)*X$11 -> 1 | Y36: =IF(Y$14<EOMONTH($E36,1),1,0)*Y$11 -> 1 | ... DL36: =IF(DL$14<EOMONTH($E36,1),1,0)*DL$11 -> 0
B37: =Rentroll!$C$29 -> B102호 | C37: =VLOOKUP($B37,Rentroll!$C$11:$X$29,3,FALSE) -> 로미오 문구점 | D37: =VLOOKUP($B37,Rentroll!$C$11:$X$29,9,FALSE) -> 44592 | E37: =VLOOKUP($B37,Rentroll!$C$11:$X$29,10,FALSE) -> 46417 | F37: =VLOOKUP($B37,Rentroll!$C$11:$X$29,11,FALSE) -> 60 | G37: =VLOOKUP($B37,Rentroll!$C$11:$X$29,13,FALSE) -> 31827 | H37: =VLOOKUP($B37,Rentroll!$C$11:$X$29,14,FALSE) -> 23870.25 | I37: =VLOOKUP($B37,Rentroll!$C$11:$X$29,15,FALSE) -> 31827 | J37: =VLOOKUP($B37,Rentroll!$C$11:$X$29,19,FALSE) -> 0.03 | K37: =VLOOKUP($B37,Rentroll!$C$11:$X$29,4,FALSE) -> 969.56 | L37: =VLOOKUP($B37,Rentroll!$C$11:$X$29,17,FALSE) -> 0 | M37: =VLOOKUP($B37,Rentroll!$C$11:$X$29,18,FALSE) -> 3 | O37: =B37 -> B102호 | R37: =IF(R$14<EOMONTH($E37,1),1,0)*R$11 -> 0 | S37: =IF(S$14<EOMONTH($E37,1),1,0)*S$11 -> 1 | T37: =IF(T$14<EOMONTH($E37,1),1,0)*T$11 -> 1 | U37: =IF(U$14<EOMONTH($E37,1),1,0)*U$11 -> 1 | V37: =IF(V$14<EOMONTH($E37,1),1,0)*V$11 -> 1 | W37: =IF(W$14<EOMONTH($E37,1),1,0)*W$11 -> 1 | X37: =IF(X$14<EOMONTH($E37,1),1,0)*X$11 -> 1 | Y37: =IF(Y$14<EOMONTH($E37,1),1,0)*Y$11 -> 1 | ... DL37: =IF(DL$14<EOMONTH($E37,1),1,0)*DL$11 -> 0
B38: 층수 | C38: 임차인 | D38: 시작일 | E38: 종료일 | F38: 기간 | G38: 명목 임대료(원) | H38: 실질 임대료(원) | I38: 관리비(원) | J38: 상승률 | K38: 임대면적(㎡) | L38: Fitout | M38: Rentfree | O38: 신규 임대차 | R38: =SUM(R39:R62) -> 0 | S38: =SUM(S39:S62) -> 3 | T38: =SUM(T39:T62) -> 3 | U38: =SUM(U39:U62) -> 7 | V38: =SUM(V39:V62) -> 7 | W38: =SUM(W39:W62) -> 7 | X38: =SUM(X39:X62) -> 9 | Y38: =SUM(Y39:Y62) -> 13 | ... DL38: =SUM(DL39:DL62) -> 0
B39: =Rentroll!$C$37 -> 17 | C39: =VLOOKUP($B39,Rentroll!$C$37:$Z$60,3,FALSE) -> 리마 상사 | D39: =VLOOKUP($B39,Rentroll!$C$37:$Z$60,9,FALSE) -> 47149 | E39: =VLOOKUP($B39,Rentroll!$C$37:$Z$60,10,FALSE) -> 48975 | F39: =VLOOKUP($B39,Rentroll!$C$37:$Z$60,11,FALSE) -> 60 | G39: =VLOOKUP($B39,Rentroll!$C$37:$Z$60,13,FALSE) -> 115927.41 | H39: =VLOOKUP($B39,Rentroll!$C$37:$Z$60,14,FALSE) -> 106266.79 | I39: =VLOOKUP($B39,Rentroll!$C$37:$Z$60,15,FALSE) -> 50647.896 | J39: =VLOOKUP($B39,Rentroll!$C$37:$Z$60,19,FALSE) -> 0.03 | K39: =VLOOKUP($B39,Rentroll!$C$37:$Z$60,4,FALSE) -> 1385.09 | L39: =VLOOKUP($B39,Rentroll!$C$37:$Z$60,17,FALSE) -> 0 | M39: =VLOOKUP($B39,Rentroll!$C$37:$Z$60,18,FALSE) -> 1 | O39: =B39 -> 17 | R39: =(R$14>$D39)*(R$14<=$E39)*R$11*1 -> 0 | S39: =(S$14>$D39)*(S$14<=$E39)*S$11*1 -> 0 | T39: =(T$14>$D39)*(T$14<=$E39)*T$11*1 -> 0 | U39: =(U$14>$D39)*(U$14<=$E39)*U$11*1 -> 0 | V39: =(V$14>$D39)*(V$14<=$E39)*V$11*1 -> 0 | W39: =(W$14>$D39)*(W$14<=$E39)*W$11*1 -> 0 | X39: =(X$14>$D39)*(X$14<=$E39)*X$11*1 -> 0 | Y39: =(Y$14>$D39)*(Y$14<=$E39)*Y$11*1 -> 0 | ... DL39: =(DL$14>$D39)*(DL$14<=$E39)*DL$11*1 -> 0
